Workbook

Sheet README
A1: Maji Safi — One Site Financial Model
A2: Safiflow Ventures Group Limited, t/a Maji Safi · Lukuli Road, Buziga, Kampala
A3: BLANK TEMPLATE — fill it in
A5: HOW THIS WORKBOOK WORKS
A6: You type in ONE tab only: ASSUMPTIONS. Yellow cells are inputs. Everything else is a formula.
A7: Change a yellow cell and the P&L, balance sheet, cash flow, break-even and ratios all move.
A8: This is the fix for the old workbook, which was a snapshot that did not recompute.
A10: THE SCENARIO SWITCH
A11: ASSUMPTIONS cell C5 is a single volume multiplier. Set it to 60% and read the cash line.
A12: That is the answer to 'what happens if we miss plan' — live, in the meeting, not after a rebuild.
A14: TABS
A15: ASSUMPTIONS every input. The only place you type.
... A38: Rows exist for the first three. They are set to zero so the gap is visible, not hidden.

Sheet ASSUMPTIONS
A1: ASSUMPTIONS — the only tab you type in
A2: Renew convention: BLUE = input · black = formula · YELLOW = live-edit decision cell.
A4: SCENARIO
A5: Volume scenario multiplier | B5: 100% = plan
A6: Set to 0.6 to see the downside. Every tab reacts. Set back to 1.0 for the plan.
A8: VOLUME
A9: Operating days per month | B9: days
A10: Jars per day — plan | B10: jars/day
A11: UNITS PER MONTH | B11: units | C11: =C9*C10*$C$5 | D11: =D9*D10*$C$5 | E11: =E9*E10*$C$5 | F11: =F9*F10*$C$5 | G11: =G9*G10*$C$5 | H11: =H9*H10*$C$5 | I11: =I9*I10*$C$5 | J11: =J9*J10*$C$5 | ... N11: =N9*N10*$C$5 | O11: =SUM(C11:N11)
A12: M1 = 500/day and M12 = 2,000/day are from the source model. M2-M11 are a straight-line ramp, DERIVED here — replace them with what sales can actually commit to.
A14: PRICE AND COST PER UNIT
A15: Net revenue per unit | B15: UGX/unit
A16: Cost of sales per unit, net of input VAT | B16: UGX/unit
A17: URA uplift — VAT + excise on net revenue | B17: % of net rev
A18: Revenue per unit FALLS across the year as the mix shifts to refill and B2C. That is intended, not an error.
A20: JAR DEPOSIT PROGRAMME
A21: LIVE EDIT — new jars issued per month | B21: jars
A22: Jar cost — expensed on issue | B22: UGX/jar
A23: Average deposit taken per jar | B23: UGX/jar
A24: Jars RETURNED and refunded per month | B24: jars
A25: Returns are set to ZERO. That is a known gap, not a fact. Put a real number here the moment you have one — every returned jar is cash out with no revenue against it.
A27: OVERHEADS
A28: Fixed operating costs | B28: UGX/month
A29: Base payroll, before the hiring step | B29: UGX/month
A30: LIVE EDIT — additional payroll from hiring | B30: UGX/month; set 0 for no-hire
A31: Hiring takes effect starting month # | B31: month
A32: Salaries and wages (computed) | B32: UGX/month | C32: =$C$29+IF(1>=$C$31,$C$30,0) | D32: =$C$29+IF(2>=$C$31,$C$30,0) | E32: =$C$29+IF(3>=$C$31,$C$30,0) | F32: =$C$29+IF(4>=$C$31,$C$30,0) | G32: =$C$29+IF(5>=$C$31,$C$30,0) | H32: =$C$29+IF(6>=$C$31,$C$30,0) | I32: =$C$29+IF(7>=$C$31,$C$30,0) | J32: =$C$29+IF(8>=$C$31,$C$30,0) | K32: =$C$29+IF(9>=$C$31,$C$30,0) | L32: =$C$29+IF(10>=$C$31,$C$30,0) | M32: =$C$29+IF(11>=$C$31,$C$30,0) | N32: =$C$29+IF(12>=$C$31,$C$30,0)
A33: Transaction fees | B33: % of gross billings
A34: Salaries step 5.3x at M5. NSSF employer is recorded at 5%; the statutory rate is 10% — CONFIRM and correct here.
A36: WORKING CAPITAL
A37: Inventory days on hand (DIO) | B37: days
A38: Debtor days (DSO) | B38: days
A39: Creditor days (DPO) | B39: days
A40: DSO and DPO are ZERO — we pay instantly and are paid instantly. The most fragile shape possible. One institution on 30 days and this stops being true.
A42: CAPITAL, TAX AND POLICY
A43: Plant and equipment at cost | B43: UGX
A44: Depreciation life | B44: months
A45: Corporate income tax rate | B45: of taxable profit
A46: Opening cash | B46: UGX
A47: Opening inventory | B47: UGX
...

Sheet P&L
A1: STATEMENT OF PROFIT OR LOSS
A2: UGX · net of VAT and excise · every cell is a formula
C4: M1 | D4: M2 | E4: M3 | F4: M4 | G4: M5 | H4: M6 | I4: M7 | J4: M8 | K4: M9 | L4: M10 | M4: M11 | N4: M12 | O4: YEAR 1
A5: Units sold | B5: units | C5: =ASSUMPTIONS!C11 | D5: =ASSUMPTIONS!D11 | E5: =ASSUMPTIONS!E11 | F5: =ASSUMPTIONS!F11 | G5: =ASSUMPTIONS!G11 | H5: =ASSUMPTIONS!H11 | I5: =ASSUMPTIONS!I11 | J5: =ASSUMPTIONS!J11 | ... N5: =ASSUMPTIONS!N11 | O5: =SUM(C5:N5)
A6: NET REVENUE | B6: UGX | C6: =ASSUMPTIONS!C11*ASSUMPTIONS!C15 | D6: =ASSUMPTIONS!D11*ASSUMPTIONS!D15 | E6: =ASSUMPTIONS!E11*ASSUMPTIONS!E15 | F6: =ASSUMPTIONS!F11*ASSUMPTIONS!F15 | G6: =ASSUMPTIONS!G11*ASSUMPTIONS!G15 | H6: =ASSUMPTIONS!H11*ASSUMPTIONS!H15 | I6: =ASSUMPTIONS!I11*ASSUMPTIONS!I15 | J6: =ASSUMPTIONS!J11*ASSUMPTIONS!J15 | ... N6: =ASSUMPTIONS!N11*ASSUMPTIONS!N15 | O6: =SUM(C6:N6)
A7: memo: gross billings (VAT-inclusive) | B7: UGX | C7: =C6*(1+ASSUMPTIONS!C17) | D7: =D6*(1+ASSUMPTIONS!D17) | E7: =E6*(1+ASSUMPTIONS!E17) | F7: =F6*(1+ASSUMPTIONS!F17) | G7: =G6*(1+ASSUMPTIONS!G17) | H7: =H6*(1+ASSUMPTIONS!H17) | I7: =I6*(1+ASSUMPTIONS!I17) | J7: =J6*(1+ASSUMPTIONS!J17) | ... N7: =N6*(1+ASSUMPTIONS!N17) | O7: =SUM(C7:N7)
A8: memo: VAT and excise collected for URA | B8: UGX | C8: =C6*ASSUMPTIONS!C17 | D8: =D6*ASSUMPTIONS!D17 | E8: =E6*ASSUMPTIONS!E17 | F8: =F6*ASSUMPTIONS!F17 | G8: =G6*ASSUMPTIONS!G17 | H8: =H6*ASSUMPTIONS!H17 | I8: =I6*ASSUMPTIONS!I17 | J8: =J6*ASSUMPTIONS!J17 | ... N8: =N6*ASSUMPTIONS!N17 | O8: =SUM(C8:N8)
A9: Cost of sales, net of input VAT | B9: UGX | C9: =-ASSUMPTIONS!C11*ASSUMPTIONS!C16 | D9: =-ASSUMPTIONS!D11*ASSUMPTIONS!D16 | E9: =-ASSUMPTIONS!E11*ASSUMPTIONS!E16 | F9: =-ASSUMPTIONS!F11*ASSUMPTIONS!F16 | G9: =-ASSUMPTIONS!G11*ASSUMPTIONS!G16 | H9: =-ASSUMPTIONS!H11*ASSUMPTIONS!H16 | I9: =-ASSUMPTIONS!I11*ASSUMPTIONS!I16 | J9: =-ASSUMPTIONS!J11*ASSUMPTIONS!J16 | ... N9: =-ASSUMPTIONS!N11*ASSUMPTIONS!N16 | O9: =SUM(C9:N9)
A10: Jar cost expensed on issue | B10: UGX | C10: =-ASSUMPTIONS!C21*ASSUMPTIONS!C22 | D10: =-ASSUMPTIONS!D21*ASSUMPTIONS!D22 | E10: =-ASSUMPTIONS!E21*ASSUMPTIONS!E22 | F10: =-ASSUMPTIONS!F21*ASSUMPTIONS!F22 | G10: =-ASSUMPTIONS!G21*ASSUMPTIONS!G22 | H10: =-ASSUMPTIONS!H21*ASSUMPTIONS!H22 | I10: =-ASSUMPTIONS!I21*ASSUMPTIONS!I22 | J10: =-ASSUMPTIONS!J21*ASSUMPTIONS!J22 | ... N10: =-ASSUMPTIONS!N21*ASSUMPTIONS!N22 | O10: =SUM(C10:N10)
A11: GROSS PROFIT | B11: UGX | C11: =C6+C9+C10 | D11: =D6+D9+D10 | E11: =E6+E9+E10 | F11: =F6+F9+F10 | G11: =G6+G9+G10 | H11: =H6+H9+H10 | I11: =I6+I9+I10 | J11: =J6+J9+J10 | ... N11: =N6+N9+N10 | O11: =SUM(C11:N11)
A12: Fixed operating costs | B12: UGX | C12: =-ASSUMPTIONS!C28 | D12: =-ASSUMPTIONS!D28 | E12: =-ASSUMPTIONS!E28 | F12: =-ASSUMPTIONS!F28 | G12: =-ASSUMPTIONS!G28 | H12: =-ASSUMPTIONS!H28 | I12: =-ASSUMPTIONS!I28 | J12: =-ASSUMPTIONS!J28 | ... N12: =-ASSUMPTIONS!N28 | O12: =SUM(C12:N12)
A13: Salaries and wages | B13: UGX | C13: =-ASSUMPTIONS!C32 | D13: =-ASSUMPTIONS!D32 | E13: =-ASSUMPTIONS!E32 | F13: =-ASSUMPTIONS!F32 | G13: =-ASSUMPTIONS!G32 | H13: =-ASSUMPTIONS!H32 | I13: =-ASSUMPTIONS!I32 | J13: =-ASSUMPTIONS!J32 | ... N13: =-ASSUMPTIONS!N32 | O13: =SUM(C13:N13)
A14: Transaction fees | B14: UGX | C14: =-C7*ASSUMPTIONS!C33 | D14: =-D7*ASSUMPTIONS!D33 | E14: =-E7*ASSUMPTIONS!E33 | F14: =-F7*ASSUMPTIONS!F33 | G14: =-G7*ASSUMPTIONS!G33 | H14: =-H7*ASSUMPTIONS!H33 | I14: =-I7*ASSUMPTIONS!I33 | J14: =-J7*ASSUMPTIONS!J33 | ... N14: =-N7*ASSUMPTIONS!N33 | O14: =SUM(C14:N14)
A15: EBITDA | B15: UGX | C15: =C11+C12+C13+C14 | D15: =D11+D12+D13+D14 | E15: =E11+E12+E13+E14 | F15: =F11+F12+F13+F14 | G15: =G11+G12+G13+G14 | H15: =H11+H12+H13+H14 | I15: =I11+I12+I13+I14 | J15: =J11+J12+J13+J14 | ... N15: =N11+N12+N13+N14 | O15: =SUM(C15:N15)
A16: Depreciation | B16: UGX | C16: =-ASSUMPTIONS!$C$43/ASSUMPTIONS!$C$44 | D16: =-ASSUMPTIONS!$C$43/ASSUMPTIONS!$C$44 | E16: =-ASSUMPTIONS!$C$43/ASSUMPTIONS!$C$44 | F16: =-ASSUMPTIONS!$C$43/ASSUMPTIONS!$C$44 | G16: =-ASSUMPTIONS!$C$43/ASSUMPTIONS!$C$44 | H16: =-ASSUMPTIONS!$C$43/ASSUMPTIONS!$C$44 | I16: =-ASSUMPTIONS!$C$43/ASSUMPTIONS!$C$44 | J16: =-ASSUMPTIONS!$C$43/ASSUMPTIONS!$C$44 | ... N16: =-ASSUMPTIONS!$C$43/ASSUMPTIONS!$C$44 | O16: =SUM(C16:N16)
A17: EBIT / PROFIT BEFORE TAX | B17: UGX | C17: =C15+C16 | D17: =D15+D16 | E17: =E15+E16 | F17: =F15+F16 | G17: =G15+G16 | H17: =H15+H16 | I17: =I15+I16 | J17: =J15+J16 | ... N17: =N15+N16 | O17: =SUM(C17:N17)
A18: Corporate tax charge | B18: UGX | C18: =-MAX(0,ASSUMPTIONS!$C$45*SUM($C$17:C17)) | D18: =-MAX(0,ASSUMPTIONS!$C$45*SUM($C$17:D17)+SUM($C$18:C18)) | E18: =-MAX(0,ASSUMPTIONS!$C$45*SUM($C$17:E17)+SUM($C$18:D18)) | F18: =-MAX(0,ASSUMPTIONS!$C$45*SUM($C$17:F17)+SUM($C$18:E18)) | G18: =-MAX(0,ASSUMPTIONS!$C$45*SUM($C$17:G17)+SUM($C$18:F18)) | H18: =-MAX(0,ASSUMPTIONS!$C$45*SUM($C$17:H17)+SUM($C$18:G18)) | I18: =-MAX(0,ASSUMPTIONS!$C$45*SUM($C$17:I17)+SUM($C$18:H18)) | J18: =-MAX(0,ASSUMPTIONS!$C$45*SUM($C$17:J17)+SUM($C$18:I18)) | K18: =-MAX(0,ASSUMPTIONS!$C$45*SUM($C$17:K17)+SUM($C$18:J18)) | ... N18: =-MAX(0,ASSUMPTIONS!$C$45*SUM($C$17:N17)+SUM($C$18:M18)) | O18: =SUM(C18:N18)
A19: NET PROFIT | B19: UGX | C19: =C17+C18 | D19: =D17+D18 | E19: =E17+E18 | F19: =F17+F18 | G19: =G17+G18 | H19: =H17+H18 | I19: =I17+I18 | J19: =J17+J18 | ... N19: =N17+N18 | O19: =SUM(C19:N19)
C21: M1 | D21: M2 | E21: M3 | F21: M4 | G21: M5 | H21: M6 | I21: M7 | J21: M8 | K21: M9 | L21: M10 | M21: M11 | N21: M12 | O21: YEAR 1
A22: Gross profit margin | B22: % net rev | C22: =C11/C6 | D22: =D11/D6 | E22: =E11/E6 | F22: =F11/F6 | G22: =G11/G6 | H22: =H11/H6 | I22: =I11/I6 | J22: =J11/J6 | ... O22: =O11/O6
A23: EBITDA margin | B23: % net rev | C23: =C15/C6 | D23: =D15/D6 | E23: =E15/E6 | F23: =F15/F6 | G23: =G15/G6 | H23: =H15/H6 | I23: =I15/I6 | J23: =J15/J6 | ... O23: =O15/O6
A24: Pre-tax margin | B24: % net rev | C24: =C17/C6 | D24: =D17/D6 | E24: =E17/E6 | F24: =F17/F6 | G24: =G17/G6 | H24: =H17/H6 | I24: =I17/I6 | J24: =J17/J6 | ... O24: =O17/O6
A25: Net profit margin | B25: % net rev | C25: =C19/C6 | D25: =D19/D6 | E25: =E19/E6 | F25: =F19/F6 | G25: =G19/G6 | H25: =H19/H6 | I25: =I19/I6 | J25: =J19/J6 | ... O25: =O19/O6

Sheet BALANCE SHEET
A1: STATEMENT OF FINANCIAL POSITION
A2: UGX · month-end · the CHECK row must read zero
C4: M1 | D4: M2 | E4: M3 | F4: M4 | G4: M5 | H4: M6 | I4: M7 | J4: M8 | K4: M9 | L4: M10 | M4: M11 | N4: M12 | O4: YEAR 1
A5: ASSETS
A6: Cash and cash equivalents | C6: ='CASH FLOW'!C18 | D6: ='CASH FLOW'!D18 | E6: ='CASH FLOW'!E18 | F6: ='CASH FLOW'!F18 | G6: ='CASH FLOW'!G18 | H6: ='CASH FLOW'!H18 | I6: ='CASH FLOW'!I18 | J6: ='CASH FLOW'!J18 | ... N6: ='CASH FLOW'!N18
A7: Inventories | C7: =-'P&L'!C9*ASSUMPTIONS!C37/30 | D7: =-'P&L'!D9*ASSUMPTIONS!D37/30 | E7: =-'P&L'!E9*ASSUMPTIONS!E37/30 | F7: =-'P&L'!F9*ASSUMPTIONS!F37/30 | G7: =-'P&L'!G9*ASSUMPTIONS!G37/30 | H7: =-'P&L'!H9*ASSUMPTIONS!H37/30 | I7: =-'P&L'!I9*ASSUMPTIONS!I37/30 | J7: =-'P&L'!J9*ASSUMPTIONS!J37/30 | ... N7: =-'P&L'!N9*ASSUMPTIONS!N37/30
A8: Trade receivables | C8: ='P&L'!C6*ASSUMPTIONS!C38/30 | D8: ='P&L'!D6*ASSUMPTIONS!D38/30 | E8: ='P&L'!E6*ASSUMPTIONS!E38/30 | F8: ='P&L'!F6*ASSUMPTIONS!F38/30 | G8: ='P&L'!G6*ASSUMPTIONS!G38/30 | H8: ='P&L'!H6*ASSUMPTIONS!H38/30 | I8: ='P&L'!I6*ASSUMPTIONS!I38/30 | J8: ='P&L'!J6*ASSUMPTIONS!J38/30 | ... N8: ='P&L'!N6*ASSUMPTIONS!N38/30
A9: Property, plant and equipment, at cost | C9: =ASSUMPTIONS!$C$43 | D9: =ASSUMPTIONS!$C$43 | E9: =ASSUMPTIONS!$C$43 | F9: =ASSUMPTIONS!$C$43 | G9: =ASSUMPTIONS!$C$43 | H9: =ASSUMPTIONS!$C$43 | I9: =ASSUMPTIONS!$C$43 | J9: =ASSUMPTIONS!$C$43 | ... N9: =ASSUMPTIONS!$C$43
A10: less accumulated depreciation | C10: =-ASSUMPTIONS!$C$43/ASSUMPTIONS!$C$44*1 | D10: =-ASSUMPTIONS!$C$43/ASSUMPTIONS!$C$44*2 | E10: =-ASSUMPTIONS!$C$43/ASSUMPTIONS!$C$44*3 | F10: =-ASSUMPTIONS!$C$43/ASSUMPTIONS!$C$44*4 | G10: =-ASSUMPTIONS!$C$43/ASSUMPTIONS!$C$44*5 | H10: =-ASSUMPTIONS!$C$43/ASSUMPTIONS!$C$44*6 | I10: =-ASSUMPTIONS!$C$43/ASSUMPTIONS!$C$44*7 | J10: =-ASSUMPTIONS!$C$43/ASSUMPTIONS!$C$44*8 | K10: =-ASSUMPTIONS!$C$43/ASSUMPTIONS!$C$44*9 | L10: =-ASSUMPTIONS!$C$43/ASSUMPTIONS!$C$44*10 | M10: =-ASSUMPTIONS!$C$43/ASSUMPTIONS!$C$44*11 | N10: =-ASSUMPTIONS!$C$43/ASSUMPTIONS!$C$44*12
A11: TOTAL ASSETS | C11: =SUM(C6:C10) | D11: =SUM(D6:D10) | E11: =SUM(E6:E10) | F11: =SUM(F6:F10) | G11: =SUM(G6:G10) | H11: =SUM(H6:H10) | I11: =SUM(I6:I10) | J11: =SUM(J6:J10) | ... N11: =SUM(N6:N10)
A13: LIABILITIES
A14: Trade and other payables | C14: =-'P&L'!C9*ASSUMPTIONS!C39/30 | D14: =-'P&L'!D9*ASSUMPTIONS!D39/30 | E14: =-'P&L'!E9*ASSUMPTIONS!E39/30 | F14: =-'P&L'!F9*ASSUMPTIONS!F39/30 | G14: =-'P&L'!G9*ASSUMPTIONS!G39/30 | H14: =-'P&L'!H9*ASSUMPTIONS!H39/30 | I14: =-'P&L'!I9*ASSUMPTIONS!I39/30 | J14: =-'P&L'!J9*ASSUMPTIONS!J39/30 | ... N14: =-'P&L'!N9*ASSUMPTIONS!N39/30
A15: Current tax payable | C15: =-SUM('P&L'!$C$18:'P&L'!C18)+SUM('CASH FLOW'!$C$14:'CASH FLOW'!C14) | D15: =-SUM('P&L'!$C$18:'P&L'!D18)+SUM('CASH FLOW'!$C$14:'CASH FLOW'!D14) | E15: =-SUM('P&L'!$C$18:'P&L'!E18)+SUM('CASH FLOW'!$C$14:'CASH FLOW'!E14) | F15: =-SUM('P&L'!$C$18:'P&L'!F18)+SUM('CASH FLOW'!$C$14:'CASH FLOW'!F14) | G15: =-SUM('P&L'!$C$18:'P&L'!G18)+SUM('CASH FLOW'!$C$14:'CASH FLOW'!G14) | H15: =-SUM('P&L'!$C$18:'P&L'!H18)+SUM('CASH FLOW'!$C$14:'CASH FLOW'!H14) | I15: =-SUM('P&L'!$C$18:'P&L'!I18)+SUM('CASH FLOW'!$C$14:'CASH FLOW'!I14) | J15: =-SUM('P&L'!$C$18:'P&L'!J18)+SUM('CASH FLOW'!$C$14:'CASH FLOW'!J14) | ... N15: =-SUM('P&L'!$C$18:'P&L'!N18)+SUM('CASH FLOW'!$C$14:'CASH FLOW'!N14)
A16: Customer deposits — refundable | C16: =(ASSUMPTIONS!C21-ASSUMPTIONS!C24)*ASSUMPTIONS!C23 | D16: =(ASSUMPTIONS!C21-ASSUMPTIONS!C24)*ASSUMPTIONS!C23+(ASSUMPTIONS!D21-ASSUMPTIONS!D24)*ASSUMPTIONS!D23 | E16: =(ASSUMPTIONS!C21-ASSUMPTIONS!C24)*ASSUMPTIONS!C23+(ASSUMPTIONS!D21-ASSUMPTIONS!D24)*ASSUMPTIONS!D23+(ASSUMPTIONS!E21-ASSUMPTIONS!E24)*ASSUMPTIONS!E23 | F16: =(ASSUMPTIONS!C21-ASSUMPTIONS!C24)*ASSUMPTIONS!C23+(ASSUMPTIONS!D21-ASSUMPTIONS!D24)*ASSUMPTIONS!D23+(ASSUMPTIONS!E21-ASSUMPTIONS!E24)*ASSUMPTIONS!E23+(ASSUMPTIONS!F21-ASSUMPTIONS!F24)*ASSUMPTIONS!F23 | G16: =(ASSUMPTIONS!C21-ASSUMPTIONS!C24)*ASSUMPTIONS!C23+(ASSUMPTIONS!D21-ASSUMPTIONS!D24)*ASSUMPTIONS!D23+(ASSUMPTIONS!E21-ASSUMPTIONS!E24)*ASSUMPTIONS!E23+(ASSUMPTIONS!F21-ASSUMPTIONS!F24)*ASSUMPTIONS!F23+(ASSUMPTIONS!G21-ASSUMPTIONS!G24)*ASSUMPTIONS!G23 | H16: =(ASSUMPTIONS!C21-ASSUMPTIONS!C24)*ASSUMPTIONS!C23+(ASSUMPTIONS!D21-ASSUMPTIONS!D24)*ASSUMPTIONS!D23+(ASSUMPTIONS!E21-ASSUMPTIONS!E24)*ASSUMPTIONS!E23+(ASSUMPTIONS!F21-ASSUMPTIONS!F24)*ASSUMPTIONS!F23+(ASSUMPTIONS!G21-ASSUMPTIONS!G24)*ASSUMPTIONS!G23+(ASSUMPTIONS!H21-ASSUMPTIONS!H24)*ASSUMPTIONS!H23 | I16: =(ASSUMPTIONS!C21-ASSUMPTIONS!C24)*ASSUMPTIONS!C23+(ASSUMPTIONS!D21-ASSUMPTIONS!D24)*ASSUMPTIONS!D23+(ASSUMPTIONS!E21-ASSUMPTIONS!E24)*ASSUMPTIONS!E23+(ASSUMPTIONS!F21-ASSUMPTIONS!F24)*ASSUMPTIONS!F23+(ASSUMPTIONS!G21-ASSUMPTIONS!G24)*ASSUMPTIONS!G23+(ASSUMPTIONS!H21-ASSUMPTIONS!H24)*ASSUMPTIONS!H23+(ASSUMPTIONS!I21-ASSUMPTIONS!I24)*ASSUMPTIONS!I23 | J16: =(ASSUMPTIONS!C21-ASSUMPTIONS!C24)*ASSUMPTIONS!C23+(ASSUMPTIONS!D21-ASSUMPTIONS!D24)*ASSUMPTIONS!D23+(ASSUMPTIONS!E21-ASSUMPTIONS!E24)*ASSUMPTIONS!E23+(ASSUMPTIONS!F21-ASSUMPTIONS!F24)*ASSUMPTIONS!F23+(ASSUMPTIONS!G21-ASSUMPTIONS!G24)*ASSUMPTIONS!G23+(ASSUMPTIONS!H21-ASSUMPTIONS!H24)*ASSUMPTIONS!H23+(ASSUMPTIONS!I21-ASSUMPTIONS!I24)*ASSUMPTIONS!I23+(ASSUMPTIONS!J21-ASSUMPTIONS!J24)*ASSUMPTIONS!J23 | K16: =(ASSUMPTIONS!C21-ASSUMPTIONS!C24)*ASSUMPTIONS!C23+(ASSUMPTIONS!D21-ASSUMPTIONS!D24)*ASSUMPTIONS!D23+(ASSUMPTIONS!E21-ASSUMPTIONS!E24)*ASSUMPTIONS!E23+(ASSUMPTIONS!F21-ASSUMPTIONS!F24)*ASSUMPTIONS!F23+(ASSUMPTIONS!G21-ASSUMPTIONS!G24)*ASSUMPTIONS!G23+(ASSUMPTIONS!H21-ASSUMPTIONS!H24)*ASSUMPTIONS!H23+(ASSUMPTIONS!I21-ASSUMPTIONS!I24)*ASSUMPTIONS!I23+(ASSUMPTIONS!J21-ASSUMPTIONS!J24)*ASSUMPTIONS!J23+(ASSUMPTIONS!K21-ASSUMPTIONS!K24)*ASSUMPTIONS!K23 | L16: =(ASSUMPTIONS!C21-ASSUMPTIONS!C24)*ASSUMPTIONS!C23+(ASSUMPTIONS!D21-ASSUMPTIONS!D24)*ASSUMPTIONS!D23+(ASSUMPTIONS!E21-ASSUMPTIONS!E24)*ASSUMPTIONS!E23+(ASSUMPTIONS!F21-ASSUMPTIONS!F24)*ASSUMPTIONS!F23+(ASSUMPTIONS!G21-ASSUMPTIONS!G24)*ASSUMPTIONS!G23+(ASSUMPTIONS!H21-ASSUMPTIONS!H24)*ASSUMPTIONS!H23+(ASSUMPTIONS!I21-ASSUMPTIONS!I24)*ASSUMPTIONS!I23+(ASSUMPTIONS!J21-ASSUMPTIONS!J24)*ASSUMPTIONS!J23+(ASSUMPTIONS!K21-ASSUMPTIONS!K24)*ASSUMPTIONS!K23+(ASSUMPTIONS!L21-ASSUMPTIONS!L24)*ASSUMPTIONS!L23 | M16: =(ASSUMPTIONS!C21-ASSUMPTIONS!C24)*ASSUMPTIONS!C23+(ASSUMPTIONS!D21-ASSUMPTIONS!D24)*ASSUMPTIONS!D23+(ASSUMPTIONS!E21-ASSUMPTIONS!E24)*ASSUMPTIONS!E23+(ASSUMPTIONS!F21-ASSUMPTIONS!F24)*ASSUMPTIONS!F23+(ASSUMPTIONS!G21-ASSUMPTIONS!G24)*ASSUMPTIONS!G23+(ASSUMPTIONS!H21-ASSUMPTIONS!H24)*ASSUMPTIONS!H23+(ASSUMPTIONS!I21-ASSUMPTIONS!I24)*ASSUMPTIONS!I23+(ASSUMPTIONS!J21-ASSUMPTIONS!J24)*ASSUMPTIONS!J23+(ASSUMPTIONS!K21-ASSUMPTIONS!K24)*ASSUMPTIONS!K23+(ASSUMPTIONS!L21-ASSUMPTIONS!L24)*ASSUMPTIONS!L23+(ASSUMPTIONS!M21-ASSUMPTIONS!M24)*ASSUMPTIONS!M23 | N16: =(ASSUMPTIONS!C21-ASSUMPTIONS!C24)*ASSUMPTIONS!C23+(ASSUMPTIONS!D21-ASSUMPTIONS!D24)*ASSUMPTIONS!D23+(ASSUMPTIONS!E21-ASSUMPTIONS!E24)*ASSUMPTIONS!E23+(ASSUMPTIONS!F21-ASSUMPTIONS!F24)*ASSUMPTIONS!F23+(ASSUMPTIONS!G21-ASSUMPTIONS!G24)*ASSUMPTIONS!G23+(ASSUMPTIONS!H21-ASSUMPTIONS!H24)*ASSUMPTIONS!H23+(ASSUMPTIONS!I21-ASSUMPTIONS!I24)*ASSUMPTIONS!I23+(ASSUMPTIONS!J21-ASSUMPTIONS!J24)*ASSUMPTIONS!J23+(ASSUMPTIONS!K21-ASSUMPTIONS!K24)*ASSUMPTIONS!K23+(ASSUMPTIONS!L21-ASSUMPTIONS!L24)*ASSUMPTIONS!L23+(ASSUMPTIONS!M21-ASSUMPTIONS!M24)*ASSUMPTIONS!M23+(ASSUMPTIONS!N21-ASSUMPTIONS!N24)*ASSUMPTIONS!N23
A17: TOTAL LIABILITIES | C17: =SUM(C14:C16) | D17: =SUM(D14:D16) | E17: =SUM(E14:E16) | F17: =SUM(F14:F16) | G17: =SUM(G14:G16) | H17: =SUM(H14:H16) | I17: =SUM(I14:I16) | J17: =SUM(J14:J16) | ... N17: =SUM(N14:N16)
A19: EQUITY
A20: Share capital and opening equity (derived) | C20: =ASSUMPTIONS!$C$46+ASSUMPTIONS!$C$47+ASSUMPTIONS!$C$43 | D20: =ASSUMPTIONS!$C$46+ASSUMPTIONS!$C$47+ASSUMPTIONS!$C$43 | E20: =ASSUMPTIONS!$C$46+ASSUMPTIONS!$C$47+ASSUMPTIONS!$C$43 | F20: =ASSUMPTIONS!$C$46+ASSUMPTIONS!$C$47+ASSUMPTIONS!$C$43 | G20: =ASSUMPTIONS!$C$46+ASSUMPTIONS!$C$47+ASSUMPTIONS!$C$43 | H20: =ASSUMPTIONS!$C$46+ASSUMPTIONS!$C$47+ASSUMPTIONS!$C$43 | I20: =ASSUMPTIONS!$C$46+ASSUMPTIONS!$C$47+ASSUMPTIONS!$C$43 | J20: =ASSUMPTIONS!$C$46+ASSUMPTIONS!$C$47+ASSUMPTIONS!$C$43 | ... N20: =ASSUMPTIONS!$C$46+ASSUMPTIONS!$C$47+ASSUMPTIONS!$C$43
A21: Retained earnings | C21: =SUM('P&L'!$C$19:'P&L'!C19) | D21: =SUM('P&L'!$C$19:'P&L'!D19) | E21: =SUM('P&L'!$C$19:'P&L'!E19) | F21: =SUM('P&L'!$C$19:'P&L'!F19) | G21: =SUM('P&L'!$C$19:'P&L'!G19) | H21: =SUM('P&L'!$C$19:'P&L'!H19) | I21: =SUM('P&L'!$C$19:'P&L'!I19) | J21: =SUM('P&L'!$C$19:'P&L'!J19) | ... N21: =SUM('P&L'!$C$19:'P&L'!N19)
A22: TOTAL EQUITY | C22: =C20+C21 | D22: =D20+D21 | E22: =E20+E21 | F22: =F20+F21 | G22: =G20+G21 | H22: =H20+H21 | I22: =I20+I21 | J22: =J20+J21 | ... N22: =N20+N21
A23: TOTAL LIABILITIES AND EQUITY | C23: =C17+C22 | D23: =D17+D22 | E23: =E17+E22 | F23: =F17+F22 | G23: =G17+G22 | H23: =H17+H22 | I23: =I17+I22 | J23: =J17+J22 | ... N23: =N17+N22
A24: CHECK — must be zero | C24: =ROUND(C23-C11,0) | D24: =ROUND(D23-D11,0) | E24: =ROUND(E23-E11,0) | F24: =ROUND(F23-F11,0) | G24: =ROUND(G23-G11,0) | H24: =ROUND(H23-H11,0) | I24: =ROUND(I23-I11,0) | J24: =ROUND(J23-J11,0) | ... N24: =ROUND(N23-N11,0)
A26: Customer deposits are the largest liability here. It is customers' money, repayable when a jar comes back. Never present it as equity, headroom, or distributable profit.

Sheet CASH FLOW
A1: STATEMENT OF CASH FLOWS
A2: UGX · indirect method
C4: M1 | D4: M2 | E4: M3 | F4: M4 | G4: M5 | H4: M6 | I4: M7 | J4: M8 | K4: M9 | L4: M10 | M4: M11 | N4: M12 | O4: YEAR 1
A5: Net profit | C5: ='P&L'!C19 | D5: ='P&L'!D19 | E5: ='P&L'!E19 | F5: ='P&L'!F19 | G5: ='P&L'!G19 | H5: ='P&L'!H19 | I5: ='P&L'!I19 | J5: ='P&L'!J19 | ... N5: ='P&L'!N19 | O5: =SUM(C5:N5)
A6: add back depreciation | C6: =-'P&L'!C16 | D6: =-'P&L'!D16 | E6: =-'P&L'!E16 | F6: =-'P&L'!F16 | G6: =-'P&L'!G16 | H6: =-'P&L'!H16 | I6: =-'P&L'!I16 | J6: =-'P&L'!J16 | ... N6: =-'P&L'!N16 | O6: =SUM(C6:N6)
A7: add back tax accrued | C7: =-'P&L'!C18 | D7: =-'P&L'!D18 | E7: =-'P&L'!E18 | F7: =-'P&L'!F18 | G7: =-'P&L'!G18 | H7: =-'P&L'!H18 | I7: =-'P&L'!I18 | J7: =-'P&L'!J18 | ... N7: =-'P&L'!N18 | O7: =SUM(C7:N7)
A8: movement in inventories | C8: =-('BALANCE SHEET'!C7-ASSUMPTIONS!$C$47) | D8: =-('BALANCE SHEET'!D7-'BALANCE SHEET'!C7) | E8: =-('BALANCE SHEET'!E7-'BALANCE SHEET'!D7) | F8: =-('BALANCE SHEET'!F7-'BALANCE SHEET'!E7) | G8: =-('BALANCE SHEET'!G7-'BALANCE SHEET'!F7) | H8: =-('BALANCE SHEET'!H7-'BALANCE SHEET'!G7) | I8: =-('BALANCE SHEET'!I7-'BALANCE SHEET'!H7) | J8: =-('BALANCE SHEET'!J7-'BALANCE SHEET'!I7) | K8: =-('BALANCE SHEET'!K7-'BALANCE SHEET'!J7) | ... N8: =-('BALANCE SHEET'!N7-'BALANCE SHEET'!M7) | O8: =SUM(C8:N8)
A9: movement in trade receivables | C9: =-'BALANCE SHEET'!C8 | D9: =-('BALANCE SHEET'!D8-'BALANCE SHEET'!C8) | E9: =-('BALANCE SHEET'!E8-'BALANCE SHEET'!D8) | F9: =-('BALANCE SHEET'!F8-'BALANCE SHEET'!E8) | G9: =-('BALANCE SHEET'!G8-'BALANCE SHEET'!F8) | H9: =-('BALANCE SHEET'!H8-'BALANCE SHEET'!G8) | I9: =-('BALANCE SHEET'!I8-'BALANCE SHEET'!H8) | J9: =-('BALANCE SHEET'!J8-'BALANCE SHEET'!I8) | K9: =-('BALANCE SHEET'!K8-'BALANCE SHEET'!J8) | ... N9: =-('BALANCE SHEET'!N8-'BALANCE SHEET'!M8) | O9: =SUM(C9:N9)
A10: movement in trade payables | C10: ='BALANCE SHEET'!C14 | D10: =('BALANCE SHEET'!D14-'BALANCE SHEET'!C14) | E10: =('BALANCE SHEET'!E14-'BALANCE SHEET'!D14) | F10: =('BALANCE SHEET'!F14-'BALANCE SHEET'!E14) | G10: =('BALANCE SHEET'!G14-'BALANCE SHEET'!F14) | H10: =('BALANCE SHEET'!H14-'BALANCE SHEET'!G14) | I10: =('BALANCE SHEET'!I14-'BALANCE SHEET'!H14) | J10: =('BALANCE SHEET'!J14-'BALANCE SHEET'!I14) | K10: =('BALANCE SHEET'!K14-'BALANCE SHEET'!J14) | ... N10: =('BALANCE SHEET'!N14-'BALANCE SHEET'!M14) | O10: =SUM(C10:N10)
A11: CASH FROM OPERATIONS | C11: =SUM(C5:C10) | D11: =SUM(D5:D10) | E11: =SUM(E5:E10) | F11: =SUM(F5:F10) | G11: =SUM(G5:G10) | H11: =SUM(H5:H10) | I11: =SUM(I5:I10) | J11: =SUM(J5:J10) | ... N11: =SUM(N5:N10) | O11: =SUM(C11:N11)
A12: customer deposits received | C12: =ASSUMPTIONS!C21*ASSUMPTIONS!C23 | D12: =ASSUMPTIONS!D21*ASSUMPTIONS!D23 | E12: =ASSUMPTIONS!E21*ASSUMPTIONS!E23 | F12: =ASSUMPTIONS!F21*ASSUMPTIONS!F23 | G12: =ASSUMPTIONS!G21*ASSUMPTIONS!G23 | H12: =ASSUMPTIONS!H21*ASSUMPTIONS!H23 | I12: =ASSUMPTIONS!I21*ASSUMPTIONS!I23 | J12: =ASSUMPTIONS!J21*ASSUMPTIONS!J23 | ... N12: =ASSUMPTIONS!N21*ASSUMPTIONS!N23 | O12: =SUM(C12:N12)
A13: customer deposits refunded | C13: =-ASSUMPTIONS!C24*ASSUMPTIONS!C23 | D13: =-ASSUMPTIONS!D24*ASSUMPTIONS!D23 | E13: =-ASSUMPTIONS!E24*ASSUMPTIONS!E23 | F13: =-ASSUMPTIONS!F24*ASSUMPTIONS!F23 | G13: =-ASSUMPTIONS!G24*ASSUMPTIONS!G23 | H13: =-ASSUMPTIONS!H24*ASSUMPTIONS!H23 | I13: =-ASSUMPTIONS!I24*ASSUMPTIONS!I23 | J13: =-ASSUMPTIONS!J24*ASSUMPTIONS!J23 | ... N13: =-ASSUMPTIONS!N24*ASSUMPTIONS!N23 | O13: =SUM(C13:N13)
A14: corporate tax PAID (quarterly) | C14: =-IF(MOD(1,3)=0,-SUM('P&L'!A18:'P&L'!C18),0) | D14: =-IF(MOD(2,3)=0,-SUM('P&L'!B18:'P&L'!D18),0) | E14: =-IF(MOD(3,3)=0,-SUM('P&L'!C18:'P&L'!E18),0) | F14: =-IF(MOD(4,3)=0,-SUM('P&L'!D18:'P&L'!F18),0) | G14: =-IF(MOD(5,3)=0,-SUM('P&L'!E18:'P&L'!G18),0) | H14: =-IF(MOD(6,3)=0,-SUM('P&L'!F18:'P&L'!H18),0) | I14: =-IF(MOD(7,3)=0,-SUM('P&L'!G18:'P&L'!I18),0) | J14: =-IF(MOD(8,3)=0,-SUM('P&L'!H18:'P&L'!J18),0) | K14: =-IF(MOD(9,3)=0,-SUM('P&L'!I18:'P&L'!K18),0) | L14: =-IF(MOD(10,3)=0,-SUM('P&L'!J18:'P&L'!L18),0) | M14: =-IF(MOD(11,3)=0,-SUM('P&L'!K18:'P&L'!M18),0) | N14: =-IF(MOD(12,3)=0,-SUM('P&L'!L18:'P&L'!N18),0) | O14: =SUM(C14:N14)
A15: capital expenditure | C15: =-ASSUMPTIONS!C51 | D15: =-ASSUMPTIONS!D51 | E15: =-ASSUMPTIONS!E51 | F15: =-ASSUMPTIONS!F51 | G15: =-ASSUMPTIONS!G51 | H15: =-ASSUMPTIONS!H51 | I15: =-ASSUMPTIONS!I51 | J15: =-ASSUMPTIONS!J51 | ... N15: =-ASSUMPTIONS!N51 | O15: =SUM(C15:N15)
A16: NET MOVEMENT IN CASH | C16: =C11+C12+C13+C14+C15 | D16: =D11+D12+D13+D14+D15 | E16: =E11+E12+E13+E14+E15 | F16: =F11+F12+F13+F14+F15 | G16: =G11+G12+G13+G14+G15 | H16: =H11+H12+H13+H14+H15 | I16: =I11+I12+I13+I14+I15 | J16: =J11+J12+J13+J14+J15 | ... N16: =N11+N12+N13+N14+N15 | O16: =SUM(C16:N16)
A17: Opening cash | C17: =ASSUMPTIONS!$C$46 | D17: =C17+C16 | E17: =D17+D16 | F17: =E17+E16 | G17: =F17+F16 | H17: =G17+G16 | I17: =H17+H16 | J17: =I17+I16 | K17: =J17+J16 | ... N17: =M17+M16
A18: CLOSING CASH | C18: =C17+C16 | D18: =D17+D16 | E18: =E17+E16 | F18: =F17+F16 | G18: =G17+G16 | H18: =H17+H16 | I18: =I17+I16 | J18: =J17+J16 | ... N18: =N17+N16
A19: Minimum cash floor (policy) | C19: =ASSUMPTIONS!$C$48 | D19: =ASSUMPTIONS!$C$48 | E19: =ASSUMPTIONS!$C$48 | F19: =ASSUMPTIONS!$C$48 | G19: =ASSUMPTIONS!$C$48 | H19: =ASSUMPTIONS!$C$48 | I19: =ASSUMPTIONS!$C$48 | J19: =ASSUMPTIONS!$C$48 | ... N19: =ASSUMPTIONS!$C$48
A20: HEADROOM over the floor | C20: =C18-C19 | D20: =D18-D19 | E20: =E18-E19 | F20: =F18-F19 | G20: =G18-G19 | H20: =H18-H19 | I20: =I18-I19 | J20: =J18-J19 | ... N20: =N18-N19
A21: ALARM | C21: =IF(C18<C19,"BREACH","ok") | D21: =IF(D18<D19,"BREACH","ok") | E21: =IF(E18<E19,"BREACH","ok") | F21: =IF(F18<F19,"BREACH","ok") | G21: =IF(G18<G19,"BREACH","ok") | H21: =IF(H18<H19,"BREACH","ok") | I21: =IF(I18<I19,"BREACH","ok") | J21: =IF(J18<J19,"BREACH","ok") | ... N21: =IF(N18<N19,"BREACH","ok")
A23: Closing cash INCLUDES customers' refundable deposits. Cash genuinely ours = closing cash less the deposit liability on the balance sheet.
A24: Cash genuinely the company's | C24: =C18-'BALANCE SHEET'!C16 | D24: =D18-'BALANCE SHEET'!D16 | E24: =E18-'BALANCE SHEET'!E16 | F24: =F18-'BALANCE SHEET'!F16 | G24: =G18-'BALANCE SHEET'!G16 | H24: =H18-'BALANCE SHEET'!H16 | I24: =I18-'BALANCE SHEET'!I16 | J24: =J18-'BALANCE SHEET'!J16 | ... N24: =N18-'BALANCE SHEET'!N16

Sheet BREAK-EVEN
A1: BREAK-EVEN
A2: Management accounting — jars per day needed to cover costs
C4: M1 | D4: M2 | E4: M3 | F4: M4 | G4: M5 | H4: M6 | I4: M7 | J4: M8 | K4: M9 | L4: M10 | M4: M11 | N4: M12 | O4: YEAR 1
A5: Contribution per unit | B5: UGX | C5: =ASSUMPTIONS!C15-ASSUMPTIONS!C16 | D5: =ASSUMPTIONS!D15-ASSUMPTIONS!D16 | E5: =ASSUMPTIONS!E15-ASSUMPTIONS!E16 | F5: =ASSUMPTIONS!F15-ASSUMPTIONS!F16 | G5: =ASSUMPTIONS!G15-ASSUMPTIONS!G16 | H5: =ASSUMPTIONS!H15-ASSUMPTIONS!H16 | I5: =ASSUMPTIONS!I15-ASSUMPTIONS!I16 | J5: =ASSUMPTIONS!J15-ASSUMPTIONS!J16 | ... N5: =ASSUMPTIONS!N15-ASSUMPTIONS!N16
A6: Fixed costs — cash (opex + salaries) | B6: UGX | C6: =ASSUMPTIONS!C28+ASSUMPTIONS!C32 | D6: =ASSUMPTIONS!D28+ASSUMPTIONS!D32 | E6: =ASSUMPTIONS!E28+ASSUMPTIONS!E32 | F6: =ASSUMPTIONS!F28+ASSUMPTIONS!F32 | G6: =ASSUMPTIONS!G28+ASSUMPTIONS!G32 | H6: =ASSUMPTIONS!H28+ASSUMPTIONS!H32 | I6: =ASSUMPTIONS!I28+ASSUMPTIONS!I32 | J6: =ASSUMPTIONS!J28+ASSUMPTIONS!J32 | ... N6: =ASSUMPTIONS!N28+ASSUMPTIONS!N32
A7: plus depreciation | B7: UGX | C7: =ASSUMPTIONS!$C$43/ASSUMPTIONS!$C$44 | D7: =ASSUMPTIONS!$C$43/ASSUMPTIONS!$C$44 | E7: =ASSUMPTIONS!$C$43/ASSUMPTIONS!$C$44 | F7: =ASSUMPTIONS!$C$43/ASSUMPTIONS!$C$44 | G7: =ASSUMPTIONS!$C$43/ASSUMPTIONS!$C$44 | H7: =ASSUMPTIONS!$C$43/ASSUMPTIONS!$C$44 | I7: =ASSUMPTIONS!$C$43/ASSUMPTIONS!$C$44 | J7: =ASSUMPTIONS!$C$43/ASSUMPTIONS!$C$44 | ... N7: =ASSUMPTIONS!$C$43/ASSUMPTIONS!$C$44
A8: plus jar programme | B8: UGX | C8: =ASSUMPTIONS!C21*ASSUMPTIONS!C22 | D8: =ASSUMPTIONS!D21*ASSUMPTIONS!D22 | E8: =ASSUMPTIONS!E21*ASSUMPTIONS!E22 | F8: =ASSUMPTIONS!F21*ASSUMPTIONS!F22 | G8: =ASSUMPTIONS!G21*ASSUMPTIONS!G22 | H8: =ASSUMPTIONS!H21*ASSUMPTIONS!H22 | I8: =ASSUMPTIONS!I21*ASSUMPTIONS!I22 | J8: =ASSUMPTIONS!J21*ASSUMPTIONS!J22 | ... N8: =ASSUMPTIONS!N21*ASSUMPTIONS!N22
A9: Cash break-even — excl jar programme | B9: jars/day | C9: =C6/C5/ASSUMPTIONS!C9 | D9: =D6/D5/ASSUMPTIONS!D9 | E9: =E6/E5/ASSUMPTIONS!E9 | F9: =F6/F5/ASSUMPTIONS!F9 | G9: =G6/G5/ASSUMPTIONS!G9 | H9: =H6/H5/ASSUMPTIONS!H9 | I9: =I6/I5/ASSUMPTIONS!I9 | J9: =J6/J5/ASSUMPTIONS!J9 | ... N9: =N6/N5/ASSUMPTIONS!N9
A10: Full break-even — excl jar programme | B10: jars/day | C10: =(C6+C7)/C5/ASSUMPTIONS!C9 | D10: =(D6+D7)/D5/ASSUMPTIONS!D9 | E10: =(E6+E7)/E5/ASSUMPTIONS!E9 | F10: =(F6+F7)/F5/ASSUMPTIONS!F9 | G10: =(G6+G7)/G5/ASSUMPTIONS!G9 | H10: =(H6+H7)/H5/ASSUMPTIONS!H9 | I10: =(I6+I7)/I5/ASSUMPTIONS!I9 | J10: =(J6+J7)/J5/ASSUMPTIONS!J9 | ... N10: =(N6+N7)/N5/ASSUMPTIONS!N9
A11: Cash break-even — INCL jar programme | B11: jars/day | C11: =(C6+C8)/C5/ASSUMPTIONS!C9 | D11: =(D6+D8)/D5/ASSUMPTIONS!D9 | E11: =(E6+E8)/E5/ASSUMPTIONS!E9 | F11: =(F6+F8)/F5/ASSUMPTIONS!F9 | G11: =(G6+G8)/G5/ASSUMPTIONS!G9 | H11: =(H6+H8)/H5/ASSUMPTIONS!H9 | I11: =(I6+I8)/I5/ASSUMPTIONS!I9 | J11: =(J6+J8)/J5/ASSUMPTIONS!J9 | ... N11: =(N6+N8)/N5/ASSUMPTIONS!N9
A12: FULL BREAK-EVEN — INCL jar programme | B12: jars/day | C12: =(C6+C7+C8)/C5/ASSUMPTIONS!C9 | D12: =(D6+D7+D8)/D5/ASSUMPTIONS!D9 | E12: =(E6+E7+E8)/E5/ASSUMPTIONS!E9 | F12: =(F6+F7+F8)/F5/ASSUMPTIONS!F9 | G12: =(G6+G7+G8)/G5/ASSUMPTIONS!G9 | H12: =(H6+H7+H8)/H5/ASSUMPTIONS!H9 | I12: =(I6+I7+I8)/I5/ASSUMPTIONS!I9 | J12: =(J6+J7+J8)/J5/ASSUMPTIONS!J9 | ... N12: =(N6+N7+N8)/N5/ASSUMPTIONS!N9
A13: Planned output | B13: jars/day | C13: =ASSUMPTIONS!C10*ASSUMPTIONS!$C$5 | D13: =ASSUMPTIONS!D10*ASSUMPTIONS!$C$5 | E13: =ASSUMPTIONS!E10*ASSUMPTIONS!$C$5 | F13: =ASSUMPTIONS!F10*ASSUMPTIONS!$C$5 | G13: =ASSUMPTIONS!G10*ASSUMPTIONS!$C$5 | H13: =ASSUMPTIONS!H10*ASSUMPTIONS!$C$5 | I13: =ASSUMPTIONS!I10*ASSUMPTIONS!$C$5 | J13: =ASSUMPTIONS!J10*ASSUMPTIONS!$C$5 | ... N13: =ASSUMPTIONS!N10*ASSUMPTIONS!$C$5
A14: HEADROOM over full break-even | B14: jars/day | C14: =C13-C12 | D14: =D13-D12 | E14: =E13-E12 | F14: =F13-F12 | G14: =G13-G12 | H14: =H13-H12 | I14: =I13-I12 | J14: =J13-J12 | ... N14: =N13-N12
A15: ALARM | C15: =IF(C14<0,"BELOW BREAK-EVEN","ok") | D15: =IF(D14<0,"BELOW BREAK-EVEN","ok") | E15: =IF(E14<0,"BELOW BREAK-EVEN","ok") | F15: =IF(F14<0,"BELOW BREAK-EVEN","ok") | G15: =IF(G14<0,"BELOW BREAK-EVEN","ok") | H15: =IF(H14<0,"BELOW BREAK-EVEN","ok") | I15: =IF(I14<0,"BELOW BREAK-EVEN","ok") | J15: =IF(J14<0,"BELOW BREAK-EVEN","ok") | ... N15: =IF(N14<0,"BELOW BREAK-EVEN","ok")
A17: Month 1 plans 500/day against a full break-even of 577/day. That is why Month 1 loses money. The whole risk sits in the first quarter, and it is a volume risk.

Sheet 13-WEEK CASH
A1: 13-WEEK ROLLING CASH FORECAST
A2: Bragg priority #1 · CFO100 Session 5 · REBUILD IT EVERY MONDAY MORNING. Standing rule, no exceptions. Type over the seeds — this is a forecast you maintain, not a report you read.
A4: Week commencing | C4: W1 | D4: W2 | E4: W3 | F4: W4 | G4: W5 | H4: W6 | I4: W7 | J4: W8 | K4: W9 | L4: W10 | M4: W11 | N4: W12 | O4: W13 | P4: 13-WK TOTAL
A5: OPENING CASH | B5: UGX | C5: =ASSUMPTIONS!$C$46 | D5: =C25 | E5: =D25 | F5: =E25 | G5: =F25 | H5: =G25 | I5: =H25 | J5: =I25 | K5: =J25 | ... O5: =N25
A6: RECEIPTS
A7: Cash sales — refill and single-use | B7: UGX | P7: =SUM(C7:O7)
A8: Jar deposits received | B8: UGX | P8: =SUM(C8:O8)
A9: Input VAT refunds from URA | B9: UGX | P9: =SUM(C9:O9)
A10: Other receipts / financing drawdown | B10: UGX | P10: =SUM(C10:O10)
A11: TOTAL RECEIPTS | B11: UGX | C11: =SUM(C7:C10) | D11: =SUM(D7:D10) | E11: =SUM(E7:E10) | F11: =SUM(F7:F10) | G11: =SUM(G7:G10) | H11: =SUM(H7:H10) | I11: =SUM(I7:I10) | J11: =SUM(J7:J10) | ... O11: =SUM(O7:O10) | P11: =SUM(C11:O11)
A12: PAYMENTS
A13: Raw materials and packaging | B13: UGX | P13: =SUM(C13:O13)
A14: Jar purchases | B14: UGX | P14: =SUM(C14:O14)
A15: Salaries, wages, PAYE and NSSF | B15: UGX | P15: =SUM(C15:O15)
A16: Fixed operating costs | B16: UGX | P16: =SUM(C16:O16)
A17: Transaction fees | B17: UGX | P17: =SUM(C17:O17)
A18: URA — VAT and excise | B18: UGX | P18: =SUM(C18:O18)
A19: URA — corporate tax | B19: UGX | P19: =SUM(C19:O19)
A20: Jar deposit REFUNDS | B20: UGX | P20: =SUM(C20:O20)
A21: Capex and other | B21: UGX | P21: =SUM(C21:O21)
A22: TOTAL PAYMENTS | B22: UGX | C22: =SUM(C13:C21) | D22: =SUM(D13:D21) | E22: =SUM(E13:E21) | F22: =SUM(F13:F21) | G22: =SUM(G13:G21) | H22: =SUM(H13:H21) | I22: =SUM(I13:I21) | J22: =SUM(J13:J21) | ... O22: =SUM(O13:O21) | P22: =SUM(C22:O22)
A24: NET MOVEMENT | B24: UGX | C24: =C11-C22 | D24: =D11-D22 | E24: =E11-E22 | F24: =F11-F22 | G24: =G11-G22 | H24: =H11-H22 | I24: =I11-I22 | J24: =J11-J22 | ... O24: =O11-O22 | P24: =SUM(C24:O24)
A25: CLOSING CASH | B25: UGX | C25: =C5+C24 | D25: =D5+D24 | E25: =E5+E24 | F25: =F5+F24 | G25: =G5+G24 | H25: =H5+H24 | I25: =I5+I24 | J25: =J5+J24 | ... O25: =O5+O24
A26: Minimum cash floor (policy) | B26: UGX | C26: =ASSUMPTIONS!$C$48 | D26: =ASSUMPTIONS!$C$48 | E26: =ASSUMPTIONS!$C$48 | F26: =ASSUMPTIONS!$C$48 | G26: =ASSUMPTIONS!$C$48 | H26: =ASSUMPTIONS!$C$48 | I26: =ASSUMPTIONS!$C$48 | J26: =ASSUMPTIONS!$C$48 | ... O26: =ASSUMPTIONS!$C$48
A27: HEADROOM | B27: UGX | C27: =C25-C26 | D27: =D25-D26 | E27: =E25-E26 | F27: =F25-F26 | G27: =G25-G26 | H27: =H25-H26 | I27: =I25-I26 | J27: =J25-J26 | ... O27: =O25-O26
A28: ALARM | C28: =IF(C25<C26,"BREACH","ok") | D28: =IF(D25<D26,"BREACH","ok") | E28: =IF(E25<E26,"BREACH","ok") | F28: =IF(F25<F26,"BREACH","ok") | G28: =IF(G25<G26,"BREACH","ok") | H28: =IF(H25<H26,"BREACH","ok") | I28: =IF(I25<I26,"BREACH","ok") | J28: =IF(J25<J26,"BREACH","ok") | ... O28: =IF(O25<O26,"BREACH","ok")
A30: Seeds are months 1-3 of the plan divided evenly across 13 weeks. They are a STARTING POINT, not a forecast.
A31: THE STANDING RULE: every Monday morning, before anything else, roll this forward one week and type what you actually expect to receive and pay. Then read the ALARM row.
A32: Renew's own Accounting and Finance Team Checklist puts this on the Finance Manager as a WEEKLY duty: 'Prepare a weekly cash collection and disbursement plan and share with all finance staff (13 weeks cash flow)'.
A33: Jar deposits received are NOT revenue. They are in here because they are cash, and cash is what this tab is about.
A34: Jar deposit REFUNDS is a row on purpose. It is currently zero and it will not stay zero.

Sheet 13-MONTH CASH
A1: ROLLING 13-MONTH CASH FLOW FORECAST
A2: Direct method, in Renew Capital's Session 5 shape. The 13-week tab answers TIMING. This tab answers PACE — can we afford the hiring step and the expansion?
A4: Month | C4: M1 | D4: M2 | E4: M3 | F4: M4 | G4: M5 | H4: M6 | I4: M7 | J4: M8 | K4: M9 | L4: M10 | M4: M11 | N4: M12 | O4: M13
A5: OPENING BALANCE | C5: =ASSUMPTIONS!$C$46 | D5: =C23 | E5: =D23 | F5: =E23 | G5: =F23 | H5: =G23 | I5: =H23 | J5: =I23 | K5: =J23 | ... O5: =N23
A6: Cash In
A7: Cash sales — refill and single-use (VAT-inclusive) | C7: =ASSUMPTIONS!C11*ASSUMPTIONS!C15*(1+ASSUMPTIONS!C17) | D7: =ASSUMPTIONS!D11*ASSUMPTIONS!D15*(1+ASSUMPTIONS!D17) | E7: =ASSUMPTIONS!E11*ASSUMPTIONS!E15*(1+ASSUMPTIONS!E17) | F7: =ASSUMPTIONS!F11*ASSUMPTIONS!F15*(1+ASSUMPTIONS!F17) | G7: =ASSUMPTIONS!G11*ASSUMPTIONS!G15*(1+ASSUMPTIONS!G17) | H7: =ASSUMPTIONS!H11*ASSUMPTIONS!H15*(1+ASSUMPTIONS!H17) | I7: =ASSUMPTIONS!I11*ASSUMPTIONS!I15*(1+ASSUMPTIONS!I17) | J7: =ASSUMPTIONS!J11*ASSUMPTIONS!J15*(1+ASSUMPTIONS!J17) | ... N7: =ASSUMPTIONS!N11*ASSUMPTIONS!N15*(1+ASSUMPTIONS!N17) | O7: =ASSUMPTIONS!N11*ASSUMPTIONS!N15*(1+ASSUMPTIONS!N17)
A8: Jar deposits received | C8: =ASSUMPTIONS!C21*ASSUMPTIONS!C23 | D8: =ASSUMPTIONS!D21*ASSUMPTIONS!D23 | E8: =ASSUMPTIONS!E21*ASSUMPTIONS!E23 | F8: =ASSUMPTIONS!F21*ASSUMPTIONS!F23 | G8: =ASSUMPTIONS!G21*ASSUMPTIONS!G23 | H8: =ASSUMPTIONS!H21*ASSUMPTIONS!H23 | I8: =ASSUMPTIONS!I21*ASSUMPTIONS!I23 | J8: =ASSUMPTIONS!J21*ASSUMPTIONS!J23 | ... N8: =ASSUMPTIONS!N21*ASSUMPTIONS!N23 | O8: =ASSUMPTIONS!N21*ASSUMPTIONS!N23
A9: Financing / other cash in | C9: 0 | D9: 0 | E9: 0 | F9: 0 | G9: 0 | H9: 0 | I9: 0 | J9: 0 | K9: 0 | L9: 0 | M9: 0 | N9: 0 | O9: 0
A10: Total Cash In | C10: =SUM(C7:C9) | D10: =SUM(D7:D9) | E10: =SUM(E7:E9) | F10: =SUM(F7:F9) | G10: =SUM(G7:G9) | H10: =SUM(H7:H9) | I10: =SUM(I7:I9) | J10: =SUM(J7:J9) | ... O10: =SUM(O7:O9)
A11: Cash Out
A12: Raw materials and packaging | C12: =ASSUMPTIONS!C11*ASSUMPTIONS!C16 | D12: =ASSUMPTIONS!D11*ASSUMPTIONS!D16 | E12: =ASSUMPTIONS!E11*ASSUMPTIONS!E16 | F12: =ASSUMPTIONS!F11*ASSUMPTIONS!F16 | G12: =ASSUMPTIONS!G11*ASSUMPTIONS!G16 | H12: =ASSUMPTIONS!H11*ASSUMPTIONS!H16 | I12: =ASSUMPTIONS!I11*ASSUMPTIONS!I16 | J12: =ASSUMPTIONS!J11*ASSUMPTIONS!J16 | ... N12: =ASSUMPTIONS!N11*ASSUMPTIONS!N16 | O12: =ASSUMPTIONS!N11*ASSUMPTIONS!N16
A13: Jar purchases | C13: =ASSUMPTIONS!C21*ASSUMPTIONS!C22 | D13: =ASSUMPTIONS!D21*ASSUMPTIONS!D22 | E13: =ASSUMPTIONS!E21*ASSUMPTIONS!E22 | F13: =ASSUMPTIONS!F21*ASSUMPTIONS!F22 | G13: =ASSUMPTIONS!G21*ASSUMPTIONS!G22 | H13: =ASSUMPTIONS!H21*ASSUMPTIONS!H22 | I13: =ASSUMPTIONS!I21*ASSUMPTIONS!I22 | J13: =ASSUMPTIONS!J21*ASSUMPTIONS!J22 | ... N13: =ASSUMPTIONS!N21*ASSUMPTIONS!N22 | O13: =ASSUMPTIONS!N21*ASSUMPTIONS!N22
A14: Payroll | C14: =ASSUMPTIONS!C32 | D14: =ASSUMPTIONS!D32 | E14: =ASSUMPTIONS!E32 | F14: =ASSUMPTIONS!F32 | G14: =ASSUMPTIONS!G32 | H14: =ASSUMPTIONS!H32 | I14: =ASSUMPTIONS!I32 | J14: =ASSUMPTIONS!J32 | ... N14: =ASSUMPTIONS!N32 | O14: =ASSUMPTIONS!N32
A15: Fixed operating costs | C15: =ASSUMPTIONS!C28 | D15: =ASSUMPTIONS!D28 | E15: =ASSUMPTIONS!E28 | F15: =ASSUMPTIONS!F28 | G15: =ASSUMPTIONS!G28 | H15: =ASSUMPTIONS!H28 | I15: =ASSUMPTIONS!I28 | J15: =ASSUMPTIONS!J28 | ... N15: =ASSUMPTIONS!N28 | O15: =ASSUMPTIONS!N28
A16: Transaction fees | C16: =C7*ASSUMPTIONS!C33 | D16: =D7*ASSUMPTIONS!D33 | E16: =E7*ASSUMPTIONS!E33 | F16: =F7*ASSUMPTIONS!F33 | G16: =G7*ASSUMPTIONS!G33 | H16: =H7*ASSUMPTIONS!H33 | I16: =I7*ASSUMPTIONS!I33 | J16: =J7*ASSUMPTIONS!J33 | ... N16: =N7*ASSUMPTIONS!N33 | O16: =O7*ASSUMPTIONS!N33
A17: URA — VAT and excise | C17: =ASSUMPTIONS!C11*ASSUMPTIONS!C15*ASSUMPTIONS!C17 | D17: =ASSUMPTIONS!D11*ASSUMPTIONS!D15*ASSUMPTIONS!D17 | E17: =ASSUMPTIONS!E11*ASSUMPTIONS!E15*ASSUMPTIONS!E17 | F17: =ASSUMPTIONS!F11*ASSUMPTIONS!F15*ASSUMPTIONS!F17 | G17: =ASSUMPTIONS!G11*ASSUMPTIONS!G15*ASSUMPTIONS!G17 | H17: =ASSUMPTIONS!H11*ASSUMPTIONS!H15*ASSUMPTIONS!H17 | I17: =ASSUMPTIONS!I11*ASSUMPTIONS!I15*ASSUMPTIONS!I17 | J17: =ASSUMPTIONS!J11*ASSUMPTIONS!J15*ASSUMPTIONS!J17 | ... N17: =ASSUMPTIONS!N11*ASSUMPTIONS!N15*ASSUMPTIONS!N17 | O17: =ASSUMPTIONS!N11*ASSUMPTIONS!N15*ASSUMPTIONS!N17
A18: URA — corporate tax (quarterly) | C18: =IF(MOD(1,3)=0,-SUM('P&L'!A18:'P&L'!C18),0) | D18: =IF(MOD(2,3)=0,-SUM('P&L'!B18:'P&L'!D18),0) | E18: =IF(MOD(3,3)=0,-SUM('P&L'!C18:'P&L'!E18),0) | F18: =IF(MOD(4,3)=0,-SUM('P&L'!D18:'P&L'!F18),0) | G18: =IF(MOD(5,3)=0,-SUM('P&L'!E18:'P&L'!G18),0) | H18: =IF(MOD(6,3)=0,-SUM('P&L'!F18:'P&L'!H18),0) | I18: =IF(MOD(7,3)=0,-SUM('P&L'!G18:'P&L'!I18),0) | J18: =IF(MOD(8,3)=0,-SUM('P&L'!H18:'P&L'!J18),0) | K18: =IF(MOD(9,3)=0,-SUM('P&L'!I18:'P&L'!K18),0) | L18: =IF(MOD(10,3)=0,-SUM('P&L'!J18:'P&L'!L18),0) | M18: =IF(MOD(11,3)=0,-SUM('P&L'!K18:'P&L'!M18),0) | N18: =IF(MOD(12,3)=0,-SUM('P&L'!L18:'P&L'!N18),0) | O18: =IF(MOD(13,3)=0,-SUM('P&L'!L18:'P&L'!N18),0)
A19: Jar deposit REFUNDS | C19: =ASSUMPTIONS!C24*ASSUMPTIONS!C23 | D19: =ASSUMPTIONS!D24*ASSUMPTIONS!D23 | E19: =ASSUMPTIONS!E24*ASSUMPTIONS!E23 | F19: =ASSUMPTIONS!F24*ASSUMPTIONS!F23 | G19: =ASSUMPTIONS!G24*ASSUMPTIONS!G23 | H19: =ASSUMPTIONS!H24*ASSUMPTIONS!H23 | I19: =ASSUMPTIONS!I24*ASSUMPTIONS!I23 | J19: =ASSUMPTIONS!J24*ASSUMPTIONS!J23 | ... N19: =ASSUMPTIONS!N24*ASSUMPTIONS!N23 | O19: =ASSUMPTIONS!N24*ASSUMPTIONS!N23
A20: Capex / one-time spending | C20: =ASSUMPTIONS!C51 | D20: =ASSUMPTIONS!D51 | E20: =ASSUMPTIONS!E51 | F20: =ASSUMPTIONS!F51 | G20: =ASSUMPTIONS!G51 | H20: =ASSUMPTIONS!H51 | I20: =ASSUMPTIONS!I51 | J20: =ASSUMPTIONS!J51 | ... N20: =ASSUMPTIONS!N51 | O20: =ASSUMPTIONS!N51
A21: Total Cash Out | C21: =SUM(C12:C20) | D21: =SUM(D12:D20) | E21: =SUM(E12:E20) | F21: =SUM(F12:F20) | G21: =SUM(G12:G20) | H21: =SUM(H12:H20) | I21: =SUM(I12:I20) | J21: =SUM(J12:J20) | ... O21: =SUM(O12:O20)
A22: Net Cash Flow | C22: =C10-C21 | D22: =D10-D21 | E22: =E10-E21 | F22: =F10-F21 | G22: =G10-G21 | H22: =H10-H21 | I22: =I10-I21 | J22: =J10-J21 | ... O22: =O10-O21
A23: CLOSING BALANCE | C23: =C5+C22 | D23: =D5+D22 | E23: =E5+E22 | F23: =F5+F22 | G23: =G5+G22 | H23: =H5+H22 | I23: =I5+I22 | J23: =J5+J22 | ... O23: =O5+O22
A24: Minimum Cash Threshold | C24: =ASSUMPTIONS!$C$48 | D24: =ASSUMPTIONS!$C$48 | E24: =ASSUMPTIONS!$C$48 | F24: =ASSUMPTIONS!$C$48 | G24: =ASSUMPTIONS!$C$48 | H24: =ASSUMPTIONS!$C$48 | I24: =ASSUMPTIONS!$C$48 | J24: =ASSUMPTIONS!$C$48 | ... O24: =ASSUMPTIONS!$C$48
A25: Cash Above / (Below) Minimum | C25: =C23-C24 | D25: =D23-D24 | E25: =E23-E24 | F25: =F23-F24 | G25: =G23-G24 | H25: =H23-H24 | I25: =I23-I24 | J25: =J23-J24 | ... O25: =O23-O24
A26: ALARM | C26: =IF(C25<0,"BELOW MINIMUM","ok") | D26: =IF(D25<0,"BELOW MINIMUM","ok") | E26: =IF(E25<0,"BELOW MINIMUM","ok") | F26: =IF(F25<0,"BELOW MINIMUM","ok") | G26: =IF(G25<0,"BELOW MINIMUM","ok") | H26: =IF(H25<0,"BELOW MINIMUM","ok") | I26: =IF(I25<0,"BELOW MINIMUM","ok") | J26: =IF(J25<0,"BELOW MINIMUM","ok") | ... O26: =IF(O25<0,"BELOW MINIMUM","ok")
A28: memo: of which customers' refundable deposits | C28: =(ASSUMPTIONS!C21-ASSUMPTIONS!C24)*ASSUMPTIONS!C23 | D28: =(ASSUMPTIONS!C21-ASSUMPTIONS!C24)*ASSUMPTIONS!C23+(ASSUMPTIONS!D21-ASSUMPTIONS!D24)*ASSUMPTIONS!D23 | E28: =(ASSUMPTIONS!C21-ASSUMPTIONS!C24)*ASSUMPTIONS!C23+(ASSUMPTIONS!D21-ASSUMPTIONS!D24)*ASSUMPTIONS!D23+(ASSUMPTIONS!E21-ASSUMPTIONS!E24)*ASSUMPTIONS!E23 | F28: =(ASSUMPTIONS!C21-ASSUMPTIONS!C24)*ASSUMPTIONS!C23+(ASSUMPTIONS!D21-ASSUMPTIONS!D24)*ASSUMPTIONS!D23+(ASSUMPTIONS!E21-ASSUMPTIONS!E24)*ASSUMPTIONS!E23+(ASSUMPTIONS!F21-ASSUMPTIONS!F24)*ASSUMPTIONS!F23 | G28: =(ASSUMPTIONS!C21-ASSUMPTIONS!C24)*ASSUMPTIONS!C23+(ASSUMPTIONS!D21-ASSUMPTIONS!D24)*ASSUMPTIONS!D23+(ASSUMPTIONS!E21-ASSUMPTIONS!E24)*ASSUMPTIONS!E23+(ASSUMPTIONS!F21-ASSUMPTIONS!F24)*ASSUMPTIONS!F23+(ASSUMPTIONS!G21-ASSUMPTIONS!G24)*ASSUMPTIONS!G23 | H28: =(ASSUMPTIONS!C21-ASSUMPTIONS!C24)*ASSUMPTIONS!C23+(ASSUMPTIONS!D21-ASSUMPTIONS!D24)*ASSUMPTIONS!D23+(ASSUMPTIONS!E21-ASSUMPTIONS!E24)*ASSUMPTIONS!E23+(ASSUMPTIONS!F21-ASSUMPTIONS!F24)*ASSUMPTIONS!F23+(ASSUMPTIONS!G21-ASSUMPTIONS!G24)*ASSUMPTIONS!G23+(ASSUMPTIONS!H21-ASSUMPTIONS!H24)*ASSUMPTIONS!H23 | I28: =(ASSUMPTIONS!C21-ASSUMPTIONS!C24)*ASSUMPTIONS!C23+(ASSUMPTIONS!D21-ASSUMPTIONS!D24)*ASSUMPTIONS!D23+(ASSUMPTIONS!E21-ASSUMPTIONS!E24)*ASSUMPTIONS!E23+(ASSUMPTIONS!F21-ASSUMPTIONS!F24)*ASSUMPTIONS!F23+(ASSUMPTIONS!G21-ASSUMPTIONS!G24)*ASSUMPTIONS!G23+(ASSUMPTIONS!H21-ASSUMPTIONS!H24)*ASSUMPTIONS!H23+(ASSUMPTIONS!I21-ASSUMPTIONS!I24)*ASSUMPTIONS!I23 | J28: =(ASSUMPTIONS!C21-ASSUMPTIONS!C24)*ASSUMPTIONS!C23+(ASSUMPTIONS!D21-ASSUMPTIONS!D24)*ASSUMPTIONS!D23+(ASSUMPTIONS!E21-ASSUMPTIONS!E24)*ASSUMPTIONS!E23+(ASSUMPTIONS!F21-ASSUMPTIONS!F24)*ASSUMPTIONS!F23+(ASSUMPTIONS!G21-ASSUMPTIONS!G24)*ASSUMPTIONS!G23+(ASSUMPTIONS!H21-ASSUMPTIONS!H24)*ASSUMPTIONS!H23+(ASSUMPTIONS!I21-ASSUMPTIONS!I24)*ASSUMPTIONS!I23+(ASSUMPTIONS!J21-ASSUMPTIONS!J24)*ASSUMPTIONS!J23 | K28: =(ASSUMPTIONS!C21-ASSUMPTIONS!C24)*ASSUMPTIONS!C23+(ASSUMPTIONS!D21-ASSUMPTIONS!D24)*ASSUMPTIONS!D23+(ASSUMPTIONS!E21-ASSUMPTIONS!E24)*ASSUMPTIONS!E23+(ASSUMPTIONS!F21-ASSUMPTIONS!F24)*ASSUMPTIONS!F23+(ASSUMPTIONS!G21-ASSUMPTIONS!G24)*ASSUMPTIONS!G23+(ASSUMPTIONS!H21-ASSUMPTIONS!H24)*ASSUMPTIONS!H23+(ASSUMPTIONS!I21-ASSUMPTIONS!I24)*ASSUMPTIONS!I23+(ASSUMPTIONS!J21-ASSUMPTIONS!J24)*ASSUMPTIONS!J23+(ASSUMPTIONS!K21-ASSUMPTIONS!K24)*ASSUMPTIONS!K23 | L28: =(ASSUMPTIONS!C21-ASSUMPTIONS!C24)*ASSUMPTIONS!C23+(ASSUMPTIONS!D21-ASSUMPTIONS!D24)*ASSUMPTIONS!D23+(ASSUMPTIONS!E21-ASSUMPTIONS!E24)*ASSUMPTIONS!E23+(ASSUMPTIONS!F21-ASSUMPTIONS!F24)*ASSUMPTIONS!F23+(ASSUMPTIONS!G21-ASSUMPTIONS!G24)*ASSUMPTIONS!G23+(ASSUMPTIONS!H21-ASSUMPTIONS!H24)*ASSUMPTIONS!H23+(ASSUMPTIONS!I21-ASSUMPTIONS!I24)*ASSUMPTIONS!I23+(ASSUMPTIONS!J21-ASSUMPTIONS!J24)*ASSUMPTIONS!J23+(ASSUMPTIONS!K21-ASSUMPTIONS!K24)*ASSUMPTIONS!K23+(ASSUMPTIONS!L21-ASSUMPTIONS!L24)*ASSUMPTIONS!L23 | M28: =(ASSUMPTIONS!C21-ASSUMPTIONS!C24)*ASSUMPTIONS!C23+(ASSUMPTIONS!D21-ASSUMPTIONS!D24)*ASSUMPTIONS!D23+(ASSUMPTIONS!E21-ASSUMPTIONS!E24)*ASSUMPTIONS!E23+(ASSUMPTIONS!F21-ASSUMPTIONS!F24)*ASSUMPTIONS!F23+(ASSUMPTIONS!G21-ASSUMPTIONS!G24)*ASSUMPTIONS!G23+(ASSUMPTIONS!H21-ASSUMPTIONS!H24)*ASSUMPTIONS!H23+(ASSUMPTIONS!I21-ASSUMPTIONS!I24)*ASSUMPTIONS!I23+(ASSUMPTIONS!J21-ASSUMPTIONS!J24)*ASSUMPTIONS!J23+(ASSUMPTIONS!K21-ASSUMPTIONS!K24)*ASSUMPTIONS!K23+(ASSUMPTIONS!L21-ASSUMPTIONS!L24)*ASSUMPTIONS!L23+(ASSUMPTIONS!M21-ASSUMPTIONS!M24)*ASSUMPTIONS!M23 | N28: =(ASSUMPTIONS!C21-ASSUMPTIONS!C24)*ASSUMPTIONS!C23+(ASSUMPTIONS!D21-ASSUMPTIONS!D24)*ASSUMPTIONS!D23+(ASSUMPTIONS!E21-ASSUMPTIONS!E24)*ASSUMPTIONS!E23+(ASSUMPTIONS!F21-ASSUMPTIONS!F24)*ASSUMPTIONS!F23+(ASSUMPTIONS!G21-ASSUMPTIONS!G24)*ASSUMPTIONS!G23+(ASSUMPTIONS!H21-ASSUMPTIONS!H24)*ASSUMPTIONS!H23+(ASSUMPTIONS!I21-ASSUMPTIONS!I24)*ASSUMPTIONS!I23+(ASSUMPTIONS!J21-ASSUMPTIONS!J24)*ASSUMPTIONS!J23+(ASSUMPTIONS!K21-ASSUMPTIONS!K24)*ASSUMPTIONS!K23+(ASSUMPTIONS!L21-ASSUMPTIONS!L24)*ASSUMPTIONS!L23+(ASSUMPTIONS!M21-ASSUMPTIONS!M24)*ASSUMPTIONS!M23+(ASSUMPTIONS!N21-ASSUMPTIONS!N24)*ASSUMPTIONS!N23 | O28: =(ASSUMPTIONS!C21-ASSUMPTIONS!C24)*ASSUMPTIONS!C23+(ASSUMPTIONS!D21-ASSUMPTIONS!D24)*ASSUMPTIONS!D23+(ASSUMPTIONS!E21-ASSUMPTIONS!E24)*ASSUMPTIONS!E23+(ASSUMPTIONS!F21-ASSUMPTIONS!F24)*ASSUMPTIONS!F23+(ASSUMPTIONS!G21-ASSUMPTIONS!G24)*ASSUMPTIONS!G23+(ASSUMPTIONS!H21-ASSUMPTIONS!H24)*ASSUMPTIONS!H23+(ASSUMPTIONS!I21-ASSUMPTIONS!I24)*ASSUMPTIONS!I23+(ASSUMPTIONS!J21-ASSUMPTIONS!J24)*ASSUMPTIONS!J23+(ASSUMPTIONS!K21-ASSUMPTIONS!K24)*ASSUMPTIONS!K23+(ASSUMPTIONS!L21-ASSUMPTIONS!L24)*ASSUMPTIONS!L23+(ASSUMPTIONS!M21-ASSUMPTIONS!M24)*ASSUMPTIONS!M23+(ASSUMPTIONS!N21-ASSUMPTIONS!N24)*ASSUMPTIONS!N23+(ASSUMPTIONS!N21-ASSUMPTIONS!N24)*ASSUMPTIONS!N23
A29: memo: cash genuinely OURS | C29: =C23-C28 | D29: =D23-D28 | E29: =E23-E28 | F29: =F23-F28 | G29: =G23-G28 | H29: =H23-H28 | I29: =I23-I28 | J29: =J23-J28 | ... O29: =O23-O28
A31: Month 13 repeats Month 12's assumptions. Replace it the moment you have a Year-2 view.
A32: THE STRUCTURAL QUESTION: set the hiring step (ASSUMPTIONS) to 0 and watch the closing balance. Then set it back.
A33: That difference is what the hire costs in cash. Renew: 'the fix here is not a timing trick, it's a decision about the pace of expansion.'
A34: Closing balance INCLUDES customers' deposits. The memo rows below strip them out. Manage to the OURS line, not the closing line.

Sheet RATIOS
A1: KEY RATIOS — the four families
A2: CFO100 Session 3 · these are FORECAST ratios. Say so before anyone else does.
A4: PROFITABILITY
A5: Gross profit margin | C5: ='P&L'!O11/'P&L'!O6 | D5: Higher is better
A6: EBITDA margin | C6: ='P&L'!O15/'P&L'!O6 | D6: Higher is better
A7: Pre-tax margin | C7: ='P&L'!O17/'P&L'!O6 | D7: 5% life support · 10% floor · 15% healthy
A8: Net profit margin | C8: ='P&L'!O19/'P&L'!O6 | D8: Higher is better
A9: Return on assets (ROA) | C9: ='P&L'!O19/AVERAGE('BALANCE SHEET'!C11:N11) | D9: FORECAST — not an achievement
A10: Return on equity (ROE) | C10: ='P&L'!O19/AVERAGE('BALANCE SHEET'!C22:N22) | D10: FORECAST — not an achievement
A12: LIQUIDITY — at Month 12
A13: Current ratio | C13: =('BALANCE SHEET'!N6+'BALANCE SHEET'!N7+'BALANCE SHEET'!N8)/'BALANCE SHEET'!N17 | D13: Ideal 1.5x - 3.0x
A14: Quick ratio | C14: =('BALANCE SHEET'!N6+'BALANCE SHEET'!N8)/'BALANCE SHEET'!N17 | D14: Above 1.0x
A15: Cash ratio | C15: ='BALANCE SHEET'!N6/'BALANCE SHEET'!N17 | D15: Ideally 1.0x
A16: Deposits as % of closing cash | C16: ='BALANCE SHEET'!N16/'BALANCE SHEET'!N6 | D16: How much of our cash is NOT ours
A18: EFFICIENCY
A19: Asset turnover | C19: ='P&L'!O6/AVERAGE('BALANCE SHEET'!C11:N11) | D19: Higher is better
A20: Days inventory outstanding (DIO) | C20: =AVERAGE(ASSUMPTIONS!C37:ASSUMPTIONS!N37)
A21: Days sales outstanding (DSO) | C21: =AVERAGE(ASSUMPTIONS!C38:ASSUMPTIONS!N38) | D21: Zero today. Will not stay zero.
A22: Days payable outstanding (DPO) | C22: =AVERAGE(ASSUMPTIONS!C39:ASSUMPTIONS!N39) | D22: Zero today. Suppliers give no credit.
A23: Cash conversion cycle | C23: =AVERAGE(ASSUMPTIONS!C37:ASSUMPTIONS!N37)+AVERAGE(ASSUMPTIONS!C38:ASSUMPTIONS!N38)-AVERAGE(ASSUMPTIONS!C39:ASSUMPTIONS!N39) | D23: Shorter is better
A25: CASH
A26: Lowest cash point in the year | C26: =MIN('CASH FLOW'!C18:N18) | D26: The thinnest the company ever gets
A27: Month of lowest cash | C27: =MATCH(MIN('CASH FLOW'!C18:N18),'CASH FLOW'!C18:N18,0)
A28: Cash genuinely ours at M12 | C28: ='CASH FLOW'!N18-'BALANCE SHEET'!N16 | D28: Closing cash less customer deposits
A29: Free cash flow (Year 1) | C29: ='CASH FLOW'!O11+'CASH FLOW'!O15 | D29: Operating cash flow less capex

Sheet CHECKS
A1: INTEGRITY CHECKS
A3: Check | B3: Model | C3: Source / target | D3: Verdict
A4: Balance sheet balances (max abs CHECK row) | B4: =MAX(ABS('BALANCE SHEET'!C24),ABS('BALANCE SHEET'!N24)) | C4: 0 | D4: =IF(ABS(B4-C4)<=MAX(1,ABS(C4)*0.01),"OK","CHECK — variance "&TEXT(B4-C4,"#,##0"))
A5: Year-1 net revenue | B5: ='P&L'!O6 | C5: 1807859712 | D5: =IF(ABS(B5-C5)<=MAX(1,ABS(C5)*0.01),"OK","CHECK — variance "&TEXT(B5-C5,"#,##0"))
A6: Year-1 net profit | B6: ='P&L'!O19 | C6: 227423239 | D6: =IF(ABS(B6-C6)<=MAX(1,ABS(C6)*0.01),"OK","CHECK — variance "&TEXT(B6-C6,"#,##0"))
A7: Lowest cash point | B7: =MIN('CASH FLOW'!C18:N18) | C7: 17548449 | D7: =IF(ABS(B7-C7)<=MAX(1,ABS(C7)*0.01),"OK","CHECK — variance "&TEXT(B7-C7,"#,##0"))
A8: M1 contribution per unit | B8: =C5 | C8: 1616.82 | D8: =IF(ABS(B8-C8)<=MAX(1,ABS(C8)*0.01),"OK","CHECK — variance "&TEXT(B8-C8,"#,##0"))
A9: M1 full break-even incl jar (jars/day) | B9: =C12 | C9: 577 | D9: =IF(ABS(B9-C9)<=MAX(1,ABS(C9)*0.01),"OK","CHECK — variance "&TEXT(B9-C9,"#,##0"))
A10: M12 customer deposits | B10: ='BALANCE SHEET'!N16 | C10: 157038750 | D10: =IF(ABS(B10-C10)<=MAX(1,ABS(C10)*0.01),"OK","CHECK — variance "&TEXT(B10-C10,"#,##0"))
A12: WHAT IS INPUT AND WHAT IS DERIVED
A13: EXACT, from the published Year-1 model: net revenue, cost of sales, VAT+excise, inventories,
A14: deposits received, salaries, fixed costs, transaction fees, plant, depreciation, tax, opening balances.
A15: DERIVED HERE, replace when you know better: jars/day for M2-M11 (straight-line between the
A16: published 500/day at M1 and 2,000/day at M12). Revenue and cost per unit follow from that ramp.
A17: SET TO ZERO ON PURPOSE, because the truth is unknown and a guess would be worse:
A18: jar returns and refunds · trade receivables · trade payables · capex · input VAT refund timing.
A19: NOT IN THIS MODEL AT ALL: NSSF employer at the statutory 10% (recorded at 5%), Local Service Tax.
A21: If a CHECK row above says OK, this workbook reproduces the published model. If you then change an
A22: assumption, it will stop matching — that is the point. The published model was a snapshot. This one moves.
