Workbook

Sheet START HERE
A1: MAJI SAFI — FINANCIAL SOURCE OF TRUTH
A2: Safiflow Ventures Group Limited, t/a Maji Safi · Lukuli Road, Buziga, Kampala
A3: Financial year 1: 1 October 2026 – 30 September 2027
A5: THIS IS THE ONLY FINANCIAL FILE.
A6: If a number is not in here, it is not a number. No side spreadsheets, no second version,
A7: no 'the one on my laptop'. One file, one truth. Everything else is a view OF this file.
A9: HOW IT IS BUILT — four layers
A10: LAYER 1 INPUT You type here and nowhere else:
A11: SETUP · CHART OF ACCOUNTS · COST BOOK · PRICE BOOK · JOURNAL · PAYROLL
A12: LAYER 2 ENGINE Never touched. Computes everything: MONTHLY · P&L · BALANCE SHEET · TvA
A13: LAYER 3 VIEWS One per audience. Read-only. Nobody edits a view:
A14: CO-FOUNDERS · INVESTORS · INTERNAL · TAX (URA) · LENDERS · GROWTH
... A40: WHAT WE STILL DO NOT KNOW → see the GAPS tab. Nothing in here is guessed silently.

Sheet SETUP
A1: SETUP
A2: Blue = you fill it in. This drives dates, tax and opening balances everywhere else.
A4: COMPANY
A5: Registered name | B5: Safiflow Ventures Group Limited
A6: Trading as | B6: Maji Safi
A7: Site | B7: Lukuli Road, Buziga, Makindye, Kampala
A8: FY1 start date | B8: 2026-10-01 | C8: First day of trading. Everything keys off this.
A10: TAX REGISTRATION — see GAPS, several unconfirmed
A11: URA TIN | C11: GAP-01
A12: VAT registered? (YES/NO) | C12: GAP-02 — changes whether output VAT is charged from day 1
A13: VAT effective date | C13: GAP-02
A14: VAT rate | B14: 0.18 | C14: Standard rate
A15: Input VAT recovery assumption | B15: 0.75 | C15: Model assumes 75%. Earned by chasing EFRIS invoices.
A16: EFRIS enrolled? (YES/NO) | C16: GAP-03 — the 75% above depends on this
A17: Excise — ad valorem rate | B17: 0.1 | C17: Law: the HIGHER of this or the specific rate
A18: Excise — specific rate (UGX/litre) | B18: 50 | C18: On a 20L jar the specific rate usually wins
A19: Digital tax stamp (UGX/unit) | B19: 15 | C19: All products, refills included
A20: Corporate income tax rate | B20: 0.3 | C20: Losses carried forward. Accrues monthly, PAID QUARTERLY.
A21: NSSF employee rate | B21: 0.05
A22: NSSF EMPLOYER rate | C22: GAP-04 — model records 5%, statutory is 10%. CONFIRM.
A23: Local Service Tax (KCCA) — in model? | B23: NO | C23: GAP-05 — absent entirely. Needs adding.
A24: Trading licence (KCCA, per year) | B24: 600000
A25: UNBS certification status | C25: GAP-06 — a delay pushes the whole ramp right
A27: OPENING BALANCES AT 1 OCTOBER 2026 — count them, do not estimate
A28: Opening cash — bank | C28: GAP-07 — actual statement balance at 30 Sep
A29: Opening cash — mobile money | C29: GAP-07
A30: Opening cash — petty cash | C30: GAP-07
A31: Opening inventory (counted) | C31: GAP-08 — physical count, not the model's 5,112,500
A32: Jars already in the field at 1 Oct | C32: GAP-09
A33: Deposits already collected at 1 Oct | C33: GAP-09 — this is a liability from day one
A34: Trade receivables at 1 Oct | C34: GAP-10
A35: Trade payables at 1 Oct | C35: GAP-10
A36: Loans outstanding at 1 Oct | C36: GAP-10
A37: Plant and equipment at cost | B37: 315000000 | C37: From the model
A38: Depreciation life (months) | B38: 60 | C38: 5 years. CONFIRM against supplier life — GAP-11
A40: POLICY
A41: MINIMUM CASH FLOOR | B41: 20000000 | C41: Below this, the alarm fires and something gets cut
A42: Variance investigation threshold — % | B42: 0.05 | C42: Investigate any line >5% AND > the amount below
A43: Variance investigation threshold — UGX | B43: 2000000 | C43: Renew gives no rule. This one is ours.
A44: Monthly close deadline | B44: 10th | C44: Renew: 'Close on the 10th!'
...

Sheet CHART OF ACCOUNTS
A1: CHART OF ACCOUNTS
A2: The controlled vocabulary. Add a line HERE before using it in JOURNAL. This is what migrates to Xero/QuickBooks.
A4: Code | B4: Account name | C4: Class | D4: Statement | E4: VAT code | F4: Notes
A5: 1000 | B5: Cash — bank | C5: Asset | D5: Balance Sheet | E5: N/A
A6: 1010 | B6: Cash — mobile money | C6: Asset | D6: Balance Sheet | E6: N/A | F6: MTN / Airtel merchant
A7: 1020 | B7: Cash — petty cash | C7: Asset | D7: Balance Sheet | E7: N/A
A8: 1100 | B8: Trade receivables | C8: Asset | D8: Balance Sheet | E8: N/A | F8: Zero in the plan. Will not stay zero.
A9: 1200 | B9: Inventory — preforms and bottles | C9: Asset | D9: Balance Sheet | E9: Std
A10: 1210 | B10: Inventory — caps and labels | C10: Asset | D10: Balance Sheet | E10: Std
A11: 1220 | B11: Inventory — jars held for issue | C11: Asset | D11: Balance Sheet | E11: Std
A12: 1230 | B12: Inventory — treatment consumables | C12: Asset | D12: Balance Sheet | E12: Std | F12: Membranes, filters, chemicals
A13: 1300 | B13: Input VAT recoverable | C13: Asset | D13: Balance Sheet | E13: N/A | F13: The 75%/90% recovery lives here
A14: 1500 | B14: Plant and equipment at cost | C14: Asset | D14: Balance Sheet | E14: Std
A15: 1510 | B15: Accumulated depreciation | C15: Asset | D15: Balance Sheet | E15: N/A | F15: Contra-asset
A16: 2000 | B16: Trade payables | C16: Liability | D16: Balance Sheet | E16: N/A | F16: Zero in the plan
A17: 2100 | B17: CUSTOMER DEPOSITS — refundable | C17: Liability | D17: Balance Sheet | E17: N/A | F17: NOT revenue. Our largest liability.
A18: 2200 | B18: Output VAT payable | C18: Liability | D18: Balance Sheet | E18: N/A | F18: Collected for URA
A19: 2210 | B19: Excise duty payable | C19: Liability | D19: Balance Sheet | E19: N/A | F19: Collected for URA
A20: 2220 | B20: Digital tax stamps payable | C20: Liability | D20: Balance Sheet | E20: N/A
A21: 2300 | B21: PAYE payable | C21: Liability | D21: Balance Sheet | E21: N/A | F21: Withheld from wages
A22: 2310 | B22: NSSF payable | C22: Liability | D22: Balance Sheet | E22: N/A | F22: Employee + employer
A23: 2320 | B23: Local Service Tax payable | C23: Liability | D23: Balance Sheet | E23: N/A | F23: GAP-05 — not yet modelled
A24: 2400 | B24: Corporate tax payable | C24: Liability | D24: Balance Sheet | E24: N/A | F24: Accrues monthly, paid quarterly
A25: 2500 | B25: Loans and borrowings | C25: Liability | D25: Balance Sheet | E25: N/A | F25: None today
A26: 3000 | B26: Share capital | C26: Equity | D26: Balance Sheet | E26: N/A | F26: GAP-12 — real cap table unknown
A27: 3100 | B27: Retained earnings | C27: Equity | D27: Balance Sheet | E27: N/A
A28: 4000 | B28: Revenue — 20L refill | C28: Revenue | D28: P&L | E28: Std | F28: NET of VAT and excise
A29: 4010 | B29: Revenue — 20L single-use | C29: Revenue | D29: P&L | E29: Std
A30: 4020 | B30: Revenue — 5L single-use | C30: Revenue | D30: P&L | E30: Std
A31: 4100 | B31: Revenue — delivery charges | C31: Revenue | D31: P&L | E31: Std | F31: If charged separately
A32: 5000 | B32: COGS — preforms and bottles | C32: Cost of sales | D32: P&L | E32: Std | F32: GAP-13 — need the bill of materials
A33: 5010 | B33: COGS — caps, labels, shrink wrap | C33: Cost of sales | D33: P&L | E33: Std | F33: GAP-13
A34: 5020 | B34: COGS — treatment chemicals | C34: Cost of sales | D34: P&L | E34: Std | F34: GAP-13
A35: 5030 | B35: COGS — membranes and filters | C35: Cost of sales | D35: P&L | E35: Std | F35: GAP-13 + GAP-11
A36: 5040 | B36: COGS — plant electricity and water | C36: Cost of sales | D36: P&L | E36: Std | F36: GAP-13
A37: 5050 | B37: COGS — digital tax stamps | C37: Cost of sales | D37: P&L | E37: N/A | F37: 15 UGX per unit
A38: 5100 | B38: JAR COST expensed on issue | C38: Cost of sales | D38: P&L | E38: Std | F38: 11,000/jar. Expensed, never capitalised.
A39: 5200 | B39: Delivery and logistics | C39: Cost of sales | D39: P&L | E39: Std | F39: GAP-14 — own vehicles or hired?
A40: 6000 | B40: Salaries and wages | C40: Operating cost | D40: P&L | E40: N/A | F40: GAP-15 — need the headcount register
A41: 6010 | B41: NSSF — employer contribution | C41: Operating cost | D41: P&L | E41: N/A | F41: GAP-04
...

Sheet COST BOOK
A1: COST BOOK — every cost we have, and what we do not yet know
A2: What we know comes from the Year-1 model. What we do not know is marked NEEDS BREAKDOWN and carried to GAPS. Nothing here is invented.
A4: Code | B4: Cost line | C4: Category | D4: FY1 amount (UGX) | E4: Basis | F4: Owner | G4: Status / what is missing
A5: 5000-5050 | B5: Cost of sales — all materials and plant inputs | C5: Cost of sales | D5: 1091364454 | E5: Per unit: 3,884 in M1 falling to 2,132 by M12 | F5: Sammy | G5: NEEDS BREAKDOWN — one blended number. Need the bill of materials per SKU: preforms, caps, labels, shrink, chemicals, membranes, plant power, water.
A6: 5100 | B6: Jar cost expensed on issue | C6: Cost of sales | D6: 99000000 | E6: 750 jars x 11,000 per month | F6: Sammy | G6: KNOWN and firm
A7: 5200 | B7: Delivery and logistics | C7: Cost of sales | E7: Unknown | F7: Sammy | G7: MISSING — is delivery inside the COGS blend or not budgeted at all? Own vehicles or hired? Fuel, driver, maintenance?
A8: 6000 | B8: Salaries and wages | C8: Operating | D8: 118900000 | E8: 2,575,000/mo, stepping to 13,575,000 at month 5 | F8: Sammy | G8: NEEDS BREAKDOWN — how many heads at each step, which roles, which are production vs admin?
A9: 6010 | B9: NSSF employer contribution | C9: Operating | E9: 5% recorded; statutory 10% | F9: Sammy | G9: UNDERSTATED — confirm the rate, then this line roughly doubles
A10: 6100-6210 | B10: Fixed operating costs — all overheads | C10: Operating | D10: 97962504 | E10: 8,163,542 per month, flat | F10: Sammy | G10: NEEDS BREAKDOWN — one blended number covering rent, power, security, internet, insurance, repairs, cleaning, licence, professional fees. We know only two pieces: licence 600,000/yr and insurance approx 150,000/mo.
A11: 6190 | B11: Marketing and customer acquisition | C11: Operating | E11: Not in the model | F11: Sammy | G11: MISSING ENTIRELY — the plan acquires 750 new jar customers every month with zero acquisition cost. That cannot be right.
A12: 6200 | B12: Transaction and bank fees | C12: Operating | D12: 12742413 | E12: 0.5% of gross billings | F12: Sammy | G12: KNOWN
A13: 7000 | B13: Depreciation | C13: Operating | D13: 63000000 | E13: 315,000,000 over 60 months | F13: Sammy | G13: KNOWN — but confirm the 5-year life and add membrane replacement
A14: 5030 | B14: Membrane and filter replacement | C14: Cost of sales | E14: Not in the model | F14: Sammy | G14: MISSING — zero maintenance capex and zero consumables replacement in a full year of running 2,000 jars/day
A15: 8000 | B15: Corporate income tax | C15: Tax | D15: 97467102 | E15: 30% of taxable profit, paid quarterly | F15: Sammy | G15: KNOWN
A16: 2200-2220 | B16: VAT, excise and digital stamps | C16: Collected for URA | D16: 740623047 | E16: 29.1% of gross billings | F16: Sammy | G16: KNOWN — and never ours
A17: 2320 | B17: Local Service Tax | C17: Tax | E17: KCCA, on employees | F17: Sammy | G17: MISSING ENTIRELY from the model
A18: 6170 | B18: Trading licence | C18: Operating | D18: 600000 | E18: KCCA per year | F18: Sammy | G18: KNOWN
A19: 9000 | B19: Bad debt provision | C19: Operating | E19: Zero — every sale is cash | F19: Sammy | G19: NOT PROVIDED — fine while DSO is 0. The first institution on 30 days changes that.
A20: 2100 | B20: Jar deposit REFUNDS | C20: Balance sheet | E20: Zero returns assumed | F20: Sammy | G20: MISSING — no return rate, no refund reserve, no forfeiture policy
B22: TOTAL COSTS WE CAN NAME (FY1) | D22: =SUM(D5:D20)
B24: Six lines above have no number at all. Four more are single blended figures hiding many lines.
B25: Until those are broken out we do not actually know our costs — we know our cost TOTAL, which is not the same thing.
B26: Renew Session 3: a gap on its own is not a finding. The reason behind it is. You cannot find a reason inside a blended number.

Sheet PRICE BOOK
A1: PRICE BOOK — two books, decided by one question: who moves the water?
A3: Product | B3: B2B floor | C3: B2B list | D3: B2C | E3: Status | F3: Notes
A4: 20L Refill | B4: 3300 | C4: 5000 | D4: 6000 | E4: ANCHORS SET | F4: Sammy, 8 Sep 2026
A5: 20L Single-Use | B5: 9000 | C5: 10050 | D5: 10350 | E5: ANCHORS SET
A6: 5L Single-Use | B6: 3450 | C6: 4500 | D6: 4800 | E6: ANCHORS SET
A7: 20L Reusable Jar (DEPOSIT) | B7: 16800 | C7: 17850 | D7: 18150 | E7: NEVER DISCOUNTED | F7: A liability, not revenue
A9: B2B VOLUME LADDER — tier set from LAST MONTH'S ACHIEVED volume, never a promise
A10: Achieved last month | B10: 20L Refill | C10: 20L Single-Use | D10: 5L | E10: Status
A11: List (base) | B11: 5000 | C11: 10050 | D11: 4500 | E11: APPROVED — Sammy 8 Sep
A12: 500+ | B12: 4400 | C12: 9700 | D12: 4150 | E12: NOT APPROVED — GAP-19
A13: 1,500+ | B13: 3800 | C13: 9350 | D13: 3800 | E13: NOT APPROVED — GAP-19
A14: 3,000+ (FLOOR) | B14: 3300 | C14: 9000 | D14: 3450 | E14: APPROVED — never below
A16: Half this ladder is still unapproved, so part of our revenue mix is assumption. And 'the floor is earned' is a sentence, not a control — nothing stops someone granting it in the moment.

Sheet JOURNAL
A1: JOURNAL — every transaction, double entry. This is the whole data-entry job.
A2: One row per side. Debits equal credits. Pick the account code from CHART OF ACCOUNTS — never type a new name here.
A4: Date | B4: Ref | C4: Account code | D4: Account name | E4: Description | F4: Counterparty | G4: Channel | H4: Product | I4: Debit | J4: Credit | K4: VAT code | L4: Source doc | M4: Entered by
D5: =IFERROR(VLOOKUP($C5,'CHART OF ACCOUNTS'!$A:$B,2,FALSE),"")
D6: =IFERROR(VLOOKUP($C6,'CHART OF ACCOUNTS'!$A:$B,2,FALSE),"")
D7: =IFERROR(VLOOKUP($C7,'CHART OF ACCOUNTS'!$A:$B,2,FALSE),"")
D8: =IFERROR(VLOOKUP($C8,'CHART OF ACCOUNTS'!$A:$B,2,FALSE),"")
D9: =IFERROR(VLOOKUP($C9,'CHART OF ACCOUNTS'!$A:$B,2,FALSE),"")
D10: =IFERROR(VLOOKUP($C10,'CHART OF ACCOUNTS'!$A:$B,2,FALSE),"")
D11: =IFERROR(VLOOKUP($C11,'CHART OF ACCOUNTS'!$A:$B,2,FALSE),"")
D12: =IFERROR(VLOOKUP($C12,'CHART OF ACCOUNTS'!$A:$B,2,FALSE),"")
D13: =IFERROR(VLOOKUP($C13,'CHART OF ACCOUNTS'!$A:$B,2,FALSE),"")
D14: =IFERROR(VLOOKUP($C14,'CHART OF ACCOUNTS'!$A:$B,2,FALSE),"")
D15: =IFERROR(VLOOKUP($C15,'CHART OF ACCOUNTS'!$A:$B,2,FALSE),"")
D16: =IFERROR(VLOOKUP($C16,'CHART OF ACCOUNTS'!$A:$B,2,FALSE),"")
... D504: =IFERROR(VLOOKUP($C504,'CHART OF ACCOUNTS'!$A:$B,2,FALSE),"")

Sheet MONTHLY
A1: MONTHLY — engine. Never type here.
A2: Net movement per account per month, built from JOURNAL with SUMIFS. Debit positive, credit negative.
A4: Code | B4: Account | C4: Oct-26 | D4: Nov-26 | E4: Dec-26 | F4: Jan-27 | G4: Feb-27 | H4: Mar-27 | I4: Apr-27 | J4: May-27 | K4: Jun-27 | L4: Jul-27 | M4: Aug-27 | N4: Sep-27 | O4: FY1 TOTAL
A5: 1000 | B5: Cash — bank | C5: =SUMIFS(JOURNAL!$I$5:$I$504,JOURNAL!$C$5:$C$504,$A5,JOURNAL!$A$5:$A$504,">="&DATE(YEAR(SETUP!$B$8),MONTH(SETUP!$B$8)+0,1),JOURNAL!$A$5:$A$504,"<="&EOMONTH(SETUP!$B$8,0))-SUMIFS(JOURNAL!$J$5:$J$504,JOURNAL!$C$5:$C$504,$A5,JOURNAL!$A$5:$A$504,">="&DATE(YEAR(SETUP!$B$8),MONTH(SETUP!$B$8)+0,1),JOURNAL!$A$5:$A$504,"<="&EOMONTH(SETUP!$B$8,0)) | D5: =SUMIFS(JOURNAL!$I$5:$I$504,JOURNAL!$C$5:$C$504,$A5,JOURNAL!$A$5:$A$504,">="&DATE(YEAR(SETUP!$B$8),MONTH(SETUP!$B$8)+1,1),JOURNAL!$A$5:$A$504,"<="&EOMONTH(SETUP!$B$8,1))-SUMIFS(JOURNAL!$J$5:$J$504,JOURNAL!$C$5:$C$504,$A5,JOURNAL!$A$5:$A$504,">="&DATE(YEAR(SETUP!$B$8),MONTH(SETUP!$B$8)+1,1),JOURNAL!$A$5:$A$504,"<="&EOMONTH(SETUP!$B$8,1)) | E5: =SUMIFS(JOURNAL!$I$5:$I$504,JOURNAL!$C$5:$C$504,$A5,JOURNAL!$A$5:$A$504,">="&DATE(YEAR(SETUP!$B$8),MONTH(SETUP!$B$8)+2,1),JOURNAL!$A$5:$A$504,"<="&EOMONTH(SETUP!$B$8,2))-SUMIFS(JOURNAL!$J$5:$J$504,JOURNAL!$C$5:$C$504,$A5,JOURNAL!$A$5:$A$504,">="&DATE(YEAR(SETUP!$B$8),MONTH(SETUP!$B$8)+2,1),JOURNAL!$A$5:$A$504,"<="&EOMONTH(SETUP!$B$8,2)) | F5: =SUMIFS(JOURNAL!$I$5:$I$504,JOURNAL!$C$5:$C$504,$A5,JOURNAL!$A$5:$A$504,">="&DATE(YEAR(SETUP!$B$8),MONTH(SETUP!$B$8)+3,1),JOURNAL!$A$5:$A$504,"<="&EOMONTH(SETUP!$B$8,3))-SUMIFS(JOURNAL!$J$5:$J$504,JOURNAL!$C$5:$C$504,$A5,JOURNAL!$A$5:$A$504,">="&DATE(YEAR(SETUP!$B$8),MONTH(SETUP!$B$8)+3,1),JOURNAL!$A$5:$A$504,"<="&EOMONTH(SETUP!$B$8,3)) | G5: =SUMIFS(JOURNAL!$I$5:$I$504,JOURNAL!$C$5:$C$504,$A5,JOURNAL!$A$5:$A$504,">="&DATE(YEAR(SETUP!$B$8),MONTH(SETUP!$B$8)+4,1),JOURNAL!$A$5:$A$504,"<="&EOMONTH(SETUP!$B$8,4))-SUMIFS(JOURNAL!$J$5:$J$504,JOURNAL!$C$5:$C$504,$A5,JOURNAL!$A$5:$A$504,">="&DATE(YEAR(SETUP!$B$8),MONTH(SETUP!$B$8)+4,1),JOURNAL!$A$5:$A$504,"<="&EOMONTH(SETUP!$B$8,4)) | H5: =SUMIFS(JOURNAL!$I$5:$I$504,JOURNAL!$C$5:$C$504,$A5,JOURNAL!$A$5:$A$504,">="&DATE(YEAR(SETUP!$B$8),MONTH(SETUP!$B$8)+5,1),JOURNAL!$A$5:$A$504,"<="&EOMONTH(SETUP!$B$8,5))-SUMIFS(JOURNAL!$J$5:$J$504,JOURNAL!$C$5:$C$504,$A5,JOURNAL!$A$5:$A$504,">="&DATE(YEAR(SETUP!$B$8),MONTH(SETUP!$B$8)+5,1),JOURNAL!$A$5:$A$504,"<="&EOMONTH(SETUP!$B$8,5)) | I5: =SUMIFS(JOURNAL!$I$5:$I$504,JOURNAL!$C$5:$C$504,$A5,JOURNAL!$A$5:$A$504,">="&DATE(YEAR(SETUP!$B$8),MONTH(SETUP!$B$8)+6,1),JOURNAL!$A$5:$A$504,"<="&EOMONTH(SETUP!$B$8,6))-SUMIFS(JOURNAL!$J$5:$J$504,JOURNAL!$C$5:$C$504,$A5,JOURNAL!$A$5:$A$504,">="&DATE(YEAR(SETUP!$B$8),MONTH(SETUP!$B$8)+6,1),JOURNAL!$A$5:$A$504,"<="&EOMONTH(SETUP!$B$8,6)) | J5: =SUMIFS(JOURNAL!$I$5:$I$504,JOURNAL!$C$5:$C$504,$A5,JOURNAL!$A$5:$A$504,">="&DATE(YEAR(SETUP!$B$8),MONTH(SETUP!$B$8)+7,1),JOURNAL!$A$5:$A$504,"<="&EOMONTH(SETUP!$B$8,7))-SUMIFS(JOURNAL!$J$5:$J$504,JOURNAL!$C$5:$C$504,$A5,JOURNAL!$A$5:$A$504,">="&DATE(YEAR(SETUP!$B$8),MONTH(SETUP!$B$8)+7,1),JOURNAL!$A$5:$A$504,"<="&EOMONTH(SETUP!$B$8,7)) | K5: =SUMIFS(JOURNAL!$I$5:$I$504,JOURNAL!$C$5:$C$504,$A5,JOURNAL!$A$5:$A$504,">="&DATE(YEAR(SETUP!$B$8),MONTH(SETUP!$B$8)+8,1),JOURNAL!$A$5:$A$504,"<="&EOMONTH(SETUP!$B$8,8))-SUMIFS(JOURNAL!$J$5:$J$504,JOURNAL!$C$5:$C$504,$A5,JOURNAL!$A$5:$A$504,">="&DATE(YEAR(SETUP!$B$8),MONTH(SETUP!$B$8)+8,1),JOURNAL!$A$5:$A$504,"<="&EOMONTH(SETUP!$B$8,8)) | L5: =SUMIFS(JOURNAL!$I$5:$I$504,JOURNAL!$C$5:$C$504,$A5,JOURNAL!$A$5:$A$504,">="&DATE(YEAR(SETUP!$B$8),MONTH(SETUP!$B$8)+9,1),JOURNAL!$A$5:$A$504,"<="&EOMONTH(SETUP!$B$8,9))-SUMIFS(JOURNAL!$J$5:$J$504,JOURNAL!$C$5:$C$504,$A5,JOURNAL!$A$5:$A$504,">="&DATE(YEAR(SETUP!$B$8),MONTH(SETUP!$B$8)+9,1),JOURNAL!$A$5:$A$504,"<="&EOMONTH(SETUP!$B$8,9)) | M5: =SUMIFS(JOURNAL!$I$5:$I$504,JOURNAL!$C$5:$C$504,$A5,JOURNAL!$A$5:$A$504,">="&DATE(YEAR(SETUP!$B$8),MONTH(SETUP!$B$8)+10,1),JOURNAL!$A$5:$A$504,"<="&EOMONTH(SETUP!$B$8,10))-SUMIFS(JOURNAL!$J$5:$J$504,JOURNAL!$C$5:$C$504,$A5,JOURNAL!$A$5:$A$504,">="&DATE(YEAR(SETUP!$B$8),MONTH(SETUP!$B$8)+10,1),JOURNAL!$A$5:$A$504,"<="&EOMONTH(SETUP!$B$8,10)) | N5: =SUMIFS(JOURNAL!$I$5:$I$504,JOURNAL!$C$5:$C$504,$A5,JOURNAL!$A$5:$A$504,">="&DATE(YEAR(SETUP!$B$8),MONTH(SETUP!$B$8)+11,1),JOURNAL!$A$5:$A$504,"<="&EOMONTH(SETUP!$B$8,11))-SUMIFS(JOURNAL!$J$5:$J$504,JOURNAL!$C$5:$C$504,$A5,JOURNAL!$A$5:$A$504,">="&DATE(YEAR(SETUP!$B$8),MONTH(SETUP!$B$8)+11,1),JOURNAL!$A$5:$A$504,"<="&EOMONTH(SETUP!$B$8,11)) | O5: =SUM(C5:N5)
A6: 1010 | B6: Cash — mobile money | C6: =SUMIFS(JOURNAL!$I$5:$I$504,JOURNAL!$C$5:$C$504,$A6,JOURNAL!$A$5:$A$504,">="&DATE(YEAR(SETUP!$B$8),MONTH(SETUP!$B$8)+0,1),JOURNAL!$A$5:$A$504,"<="&EOMONTH(SETUP!$B$8,0))-SUMIFS(JOURNAL!$J$5:$J$504,JOURNAL!$C$5:$C$504,$A6,JOURNAL!$A$5:$A$504,">="&DATE(YEAR(SETUP!$B$8),MONTH(SETUP!$B$8)+0,1),JOURNAL!$A$5:$A$504,"<="&EOMONTH(SETUP!$B$8,0)) | D6: =SUMIFS(JOURNAL!$I$5:$I$504,JOURNAL!$C$5:$C$504,$A6,JOURNAL!$A$5:$A$504,">="&DATE(YEAR(SETUP!$B$8),MONTH(SETUP!$B$8)+1,1),JOURNAL!$A$5:$A$504,"<="&EOMONTH(SETUP!$B$8,1))-SUMIFS(JOURNAL!$J$5:$J$504,JOURNAL!$C$5:$C$504,$A6,JOURNAL!$A$5:$A$504,">="&DATE(YEAR(SETUP!$B$8),MONTH(SETUP!$B$8)+1,1),JOURNAL!$A$5:$A$504,"<="&EOMONTH(SETUP!$B$8,1)) | E6: =SUMIFS(JOURNAL!$I$5:$I$504,JOURNAL!$C$5:$C$504,$A6,JOURNAL!$A$5:$A$504,">="&DATE(YEAR(SETUP!$B$8),MONTH(SETUP!$B$8)+2,1),JOURNAL!$A$5:$A$504,"<="&EOMONTH(SETUP!$B$8,2))-SUMIFS(JOURNAL!$J$5:$J$504,JOURNAL!$C$5:$C$504,$A6,JOURNAL!$A$5:$A$504,">="&DATE(YEAR(SETUP!$B$8),MONTH(SETUP!$B$8)+2,1),JOURNAL!$A$5:$A$504,"<="&EOMONTH(SETUP!$B$8,2)) | F6: =SUMIFS(JOURNAL!$I$5:$I$504,JOURNAL!$C$5:$C$504,$A6,JOURNAL!$A$5:$A$504,">="&DATE(YEAR(SETUP!$B$8),MONTH(SETUP!$B$8)+3,1),JOURNAL!$A$5:$A$504,"<="&EOMONTH(SETUP!$B$8,3))-SUMIFS(JOURNAL!$J$5:$J$504,JOURNAL!$C$5:$C$504,$A6,JOURNAL!$A$5:$A$504,">="&DATE(YEAR(SETUP!$B$8),MONTH(SETUP!$B$8)+3,1),JOURNAL!$A$5:$A$504,"<="&EOMONTH(SETUP!$B$8,3)) | G6: =SUMIFS(JOURNAL!$I$5:$I$504,JOURNAL!$C$5:$C$504,$A6,JOURNAL!$A$5:$A$504,">="&DATE(YEAR(SETUP!$B$8),MONTH(SETUP!$B$8)+4,1),JOURNAL!$A$5:$A$504,"<="&EOMONTH(SETUP!$B$8,4))-SUMIFS(JOURNAL!$J$5:$J$504,JOURNAL!$C$5:$C$504,$A6,JOURNAL!$A$5:$A$504,">="&DATE(YEAR(SETUP!$B$8),MONTH(SETUP!$B$8)+4,1),JOURNAL!$A$5:$A$504,"<="&EOMONTH(SETUP!$B$8,4)) | H6: =SUMIFS(JOURNAL!$I$5:$I$504,JOURNAL!$C$5:$C$504,$A6,JOURNAL!$A$5:$A$504,">="&DATE(YEAR(SETUP!$B$8),MONTH(SETUP!$B$8)+5,1),JOURNAL!$A$5:$A$504,"<="&EOMONTH(SETUP!$B$8,5))-SUMIFS(JOURNAL!$J$5:$J$504,JOURNAL!$C$5:$C$504,$A6,JOURNAL!$A$5:$A$504,">="&DATE(YEAR(SETUP!$B$8),MONTH(SETUP!$B$8)+5,1),JOURNAL!$A$5:$A$504,"<="&EOMONTH(SETUP!$B$8,5)) | I6: =SUMIFS(JOURNAL!$I$5:$I$504,JOURNAL!$C$5:$C$504,$A6,JOURNAL!$A$5:$A$504,">="&DATE(YEAR(SETUP!$B$8),MONTH(SETUP!$B$8)+6,1),JOURNAL!$A$5:$A$504,"<="&EOMONTH(SETUP!$B$8,6))-SUMIFS(JOURNAL!$J$5:$J$504,JOURNAL!$C$5:$C$504,$A6,JOURNAL!$A$5:$A$504,">="&DATE(YEAR(SETUP!$B$8),MONTH(SETUP!$B$8)+6,1),JOURNAL!$A$5:$A$504,"<="&EOMONTH(SETUP!$B$8,6)) | J6: =SUMIFS(JOURNAL!$I$5:$I$504,JOURNAL!$C$5:$C$504,$A6,JOURNAL!$A$5:$A$504,">="&DATE(YEAR(SETUP!$B$8),MONTH(SETUP!$B$8)+7,1),JOURNAL!$A$5:$A$504,"<="&EOMONTH(SETUP!$B$8,7))-SUMIFS(JOURNAL!$J$5:$J$504,JOURNAL!$C$5:$C$504,$A6,JOURNAL!$A$5:$A$504,">="&DATE(YEAR(SETUP!$B$8),MONTH(SETUP!$B$8)+7,1),JOURNAL!$A$5:$A$504,"<="&EOMONTH(SETUP!$B$8,7)) | K6: =SUMIFS(JOURNAL!$I$5:$I$504,JOURNAL!$C$5:$C$504,$A6,JOURNAL!$A$5:$A$504,">="&DATE(YEAR(SETUP!$B$8),MONTH(SETUP!$B$8)+8,1),JOURNAL!$A$5:$A$504,"<="&EOMONTH(SETUP!$B$8,8))-SUMIFS(JOURNAL!$J$5:$J$504,JOURNAL!$C$5:$C$504,$A6,JOURNAL!$A$5:$A$504,">="&DATE(YEAR(SETUP!$B$8),MONTH(SETUP!$B$8)+8,1),JOURNAL!$A$5:$A$504,"<="&EOMONTH(SETUP!$B$8,8)) | L6: =SUMIFS(JOURNAL!$I$5:$I$504,JOURNAL!$C$5:$C$504,$A6,JOURNAL!$A$5:$A$504,">="&DATE(YEAR(SETUP!$B$8),MONTH(SETUP!$B$8)+9,1),JOURNAL!$A$5:$A$504,"<="&EOMONTH(SETUP!$B$8,9))-SUMIFS(JOURNAL!$J$5:$J$504,JOURNAL!$C$5:$C$504,$A6,JOURNAL!$A$5:$A$504,">="&DATE(YEAR(SETUP!$B$8),MONTH(SETUP!$B$8)+9,1),JOURNAL!$A$5:$A$504,"<="&EOMONTH(SETUP!$B$8,9)) | M6: =SUMIFS(JOURNAL!$I$5:$I$504,JOURNAL!$C$5:$C$504,$A6,JOURNAL!$A$5:$A$504,">="&DATE(YEAR(SETUP!$B$8),MONTH(SETUP!$B$8)+10,1),JOURNAL!$A$5:$A$504,"<="&EOMONTH(SETUP!$B$8,10))-SUMIFS(JOURNAL!$J$5:$J$504,JOURNAL!$C$5:$C$504,$A6,JOURNAL!$A$5:$A$504,">="&DATE(YEAR(SETUP!$B$8),MONTH(SETUP!$B$8)+10,1),JOURNAL!$A$5:$A$504,"<="&EOMONTH(SETUP!$B$8,10)) | N6: =SUMIFS(JOURNAL!$I$5:$I$504,JOURNAL!$C$5:$C$504,$A6,JOURNAL!$A$5:$A$504,">="&DATE(YEAR(SETUP!$B$8),MONTH(SETUP!$B$8)+11,1),JOURNAL!$A$5:$A$504,"<="&EOMONTH(SETUP!$B$8,11))-SUMIFS(JOURNAL!$J$5:$J$504,JOURNAL!$C$5:$C$504,$A6,JOURNAL!$A$5:$A$504,">="&DATE(YEAR(SETUP!$B$8),MONTH(SETUP!$B$8)+11,1),JOURNAL!$A$5:$A$504,"<="&EOMONTH(SETUP!$B$8,11)) | O6: =SUM(C6:N6)
A7: 1020 | B7: Cash — petty cash | C7: =SUMIFS(JOURNAL!$I$5:$I$504,JOURNAL!$C$5:$C$504,$A7,JOURNAL!$A$5:$A$504,">="&DATE(YEAR(SETUP!$B$8),MONTH(SETUP!$B$8)+0,1),JOURNAL!$A$5:$A$504,"<="&EOMONTH(SETUP!$B$8,0))-SUMIFS(JOURNAL!$J$5:$J$504,JOURNAL!$C$5:$C$504,$A7,JOURNAL!$A$5:$A$504,">="&DATE(YEAR(SETUP!$B$8),MONTH(SETUP!$B$8)+0,1),JOURNAL!$A$5:$A$504,"<="&EOMONTH(SETUP!$B$8,0)) | D7: =SUMIFS(JOURNAL!$I$5:$I$504,JOURNAL!$C$5:$C$504,$A7,JOURNAL!$A$5:$A$504,">="&DATE(YEAR(SETUP!$B$8),MONTH(SETUP!$B$8)+1,1),JOURNAL!$A$5:$A$504,"<="&EOMONTH(SETUP!$B$8,1))-SUMIFS(JOURNAL!$J$5:$J$504,JOURNAL!$C$5:$C$504,$A7,JOURNAL!$A$5:$A$504,">="&DATE(YEAR(SETUP!$B$8),MONTH(SETUP!$B$8)+1,1),JOURNAL!$A$5:$A$504,"<="&EOMONTH(SETUP!$B$8,1)) | E7: =SUMIFS(JOURNAL!$I$5:$I$504,JOURNAL!$C$5:$C$504,$A7,JOURNAL!$A$5:$A$504,">="&DATE(YEAR(SETUP!$B$8),MONTH(SETUP!$B$8)+2,1),JOURNAL!$A$5:$A$504,"<="&EOMONTH(SETUP!$B$8,2))-SUMIFS(JOURNAL!$J$5:$J$504,JOURNAL!$C$5:$C$504,$A7,JOURNAL!$A$5:$A$504,">="&DATE(YEAR(SETUP!$B$8),MONTH(SETUP!$B$8)+2,1),JOURNAL!$A$5:$A$504,"<="&EOMONTH(SETUP!$B$8,2)) | F7: =SUMIFS(JOURNAL!$I$5:$I$504,JOURNAL!$C$5:$C$504,$A7,JOURNAL!$A$5:$A$504,">="&DATE(YEAR(SETUP!$B$8),MONTH(SETUP!$B$8)+3,1),JOURNAL!$A$5:$A$504,"<="&EOMONTH(SETUP!$B$8,3))-SUMIFS(JOURNAL!$J$5:$J$504,JOURNAL!$C$5:$C$504,$A7,JOURNAL!$A$5:$A$504,">="&DATE(YEAR(SETUP!$B$8),MONTH(SETUP!$B$8)+3,1),JOURNAL!$A$5:$A$504,"<="&EOMONTH(SETUP!$B$8,3)) | G7: =SUMIFS(JOURNAL!$I$5:$I$504,JOURNAL!$C$5:$C$504,$A7,JOURNAL!$A$5:$A$504,">="&DATE(YEAR(SETUP!$B$8),MONTH(SETUP!$B$8)+4,1),JOURNAL!$A$5:$A$504,"<="&EOMONTH(SETUP!$B$8,4))-SUMIFS(JOURNAL!$J$5:$J$504,JOURNAL!$C$5:$C$504,$A7,JOURNAL!$A$5:$A$504,">="&DATE(YEAR(SETUP!$B$8),MONTH(SETUP!$B$8)+4,1),JOURNAL!$A$5:$A$504,"<="&EOMONTH(SETUP!$B$8,4)) | H7: =SUMIFS(JOURNAL!$I$5:$I$504,JOURNAL!$C$5:$C$504,$A7,JOURNAL!$A$5:$A$504,">="&DATE(YEAR(SETUP!$B$8),MONTH(SETUP!$B$8)+5,1),JOURNAL!$A$5:$A$504,"<="&EOMONTH(SETUP!$B$8,5))-SUMIFS(JOURNAL!$J$5:$J$504,JOURNAL!$C$5:$C$504,$A7,JOURNAL!$A$5:$A$504,">="&DATE(YEAR(SETUP!$B$8),MONTH(SETUP!$B$8)+5,1),JOURNAL!$A$5:$A$504,"<="&EOMONTH(SETUP!$B$8,5)) | I7: =SUMIFS(JOURNAL!$I$5:$I$504,JOURNAL!$C$5:$C$504,$A7,JOURNAL!$A$5:$A$504,">="&DATE(YEAR(SETUP!$B$8),MONTH(SETUP!$B$8)+6,1),JOURNAL!$A$5:$A$504,"<="&EOMONTH(SETUP!$B$8,6))-SUMIFS(JOURNAL!$J$5:$J$504,JOURNAL!$C$5:$C$504,$A7,JOURNAL!$A$5:$A$504,">="&DATE(YEAR(SETUP!$B$8),MONTH(SETUP!$B$8)+6,1),JOURNAL!$A$5:$A$504,"<="&EOMONTH(SETUP!$B$8,6)) | J7: =SUMIFS(JOURNAL!$I$5:$I$504,JOURNAL!$C$5:$C$504,$A7,JOURNAL!$A$5:$A$504,">="&DATE(YEAR(SETUP!$B$8),MONTH(SETUP!$B$8)+7,1),JOURNAL!$A$5:$A$504,"<="&EOMONTH(SETUP!$B$8,7))-SUMIFS(JOURNAL!$J$5:$J$504,JOURNAL!$C$5:$C$504,$A7,JOURNAL!$A$5:$A$504,">="&DATE(YEAR(SETUP!$B$8),MONTH(SETUP!$B$8)+7,1),JOURNAL!$A$5:$A$504,"<="&EOMONTH(SETUP!$B$8,7)) | K7: =SUMIFS(JOURNAL!$I$5:$I$504,JOURNAL!$C$5:$C$504,$A7,JOURNAL!$A$5:$A$504,">="&DATE(YEAR(SETUP!$B$8),MONTH(SETUP!$B$8)+8,1),JOURNAL!$A$5:$A$504,"<="&EOMONTH(SETUP!$B$8,8))-SUMIFS(JOURNAL!$J$5:$J$504,JOURNAL!$C$5:$C$504,$A7,JOURNAL!$A$5:$A$504,">="&DATE(YEAR(SETUP!$B$8),MONTH(SETUP!$B$8)+8,1),JOURNAL!$A$5:$A$504,"<="&EOMONTH(SETUP!$B$8,8)) | L7: =SUMIFS(JOURNAL!$I$5:$I$504,JOURNAL!$C$5:$C$504,$A7,JOURNAL!$A$5:$A$504,">="&DATE(YEAR(SETUP!$B$8),MONTH(SETUP!$B$8)+9,1),JOURNAL!$A$5:$A$504,"<="&EOMONTH(SETUP!$B$8,9))-SUMIFS(JOURNAL!$J$5:$J$504,JOURNAL!$C$5:$C$504,$A7,JOURNAL!$A$5:$A$504,">="&DATE(YEAR(SETUP!$B$8),MONTH(SETUP!$B$8)+9,1),JOURNAL!$A$5:$A$504,"<="&EOMONTH(SETUP!$B$8,9)) | M7: =SUMIFS(JOURNAL!$I$5:$I$504,JOURNAL!$C$5:$C$504,$A7,JOURNAL!$A$5:$A$504,">="&DATE(YEAR(SETUP!$B$8),MONTH(SETUP!$B$8)+10,1),JOURNAL!$A$5:$A$504,"<="&EOMONTH(SETUP!$B$8,10))-SUMIFS(JOURNAL!$J$5:$J$504,JOURNAL!$C$5:$C$504,$A7,JOURNAL!$A$5:$A$504,">="&DATE(YEAR(SETUP!$B$8),MONTH(SETUP!$B$8)+10,1),JOURNAL!$A$5:$A$504,"<="&EOMONTH(SETUP!$B$8,10)) | N7: =SUMIFS(JOURNAL!$I$5:$I$504,JOURNAL!$C$5:$C$504,$A7,JOURNAL!$A$5:$A$504,">="&DATE(YEAR(SETUP!$B$8),MONTH(SETUP!$B$8)+11,1),JOURNAL!$A$5:$A$504,"<="&EOMONTH(SETUP!$B$8,11))-SUMIFS(JOURNAL!$J$5:$J$504,JOURNAL!$C$5:$C$504,$A7,JOURNAL!$A$5:$A$504,">="&DATE(YEAR(SETUP!$B$8),MONTH(SETUP!$B$8)+11,1),JOURNAL!$A$5:$A$504,"<="&EOMONTH(SETUP!$B$8,11)) | O7: =SUM(C7:N7)
A8: 1100 | B8: Trade receivables | C8: =SUMIFS(JOURNAL!$I$5:$I$504,JOURNAL!$C$5:$C$504,$A8,JOURNAL!$A$5:$A$504,">="&DATE(YEAR(SETUP!$B$8),MONTH(SETUP!$B$8)+0,1),JOURNAL!$A$5:$A$504,"<="&EOMONTH(SETUP!$B$8,0))-SUMIFS(JOURNAL!$J$5:$J$504,JOURNAL!$C$5:$C$504,$A8,JOURNAL!$A$5:$A$504,">="&DATE(YEAR(SETUP!$B$8),MONTH(SETUP!$B$8)+0,1),JOURNAL!$A$5:$A$504,"<="&EOMONTH(SETUP!$B$8,0)) | D8: =SUMIFS(JOURNAL!$I$5:$I$504,JOURNAL!$C$5:$C$504,$A8,JOURNAL!$A$5:$A$504,">="&DATE(YEAR(SETUP!$B$8),MONTH(SETUP!$B$8)+1,1),JOURNAL!$A$5:$A$504,"<="&EOMONTH(SETUP!$B$8,1))-SUMIFS(JOURNAL!$J$5:$J$504,JOURNAL!$C$5:$C$504,$A8,JOURNAL!$A$5:$A$504,">="&DATE(YEAR(SETUP!$B$8),MONTH(SETUP!$B$8)+1,1),JOURNAL!$A$5:$A$504,"<="&EOMONTH(SETUP!$B$8,1)) | E8: =SUMIFS(JOURNAL!$I$5:$I$504,JOURNAL!$C$5:$C$504,$A8,JOURNAL!$A$5:$A$504,">="&DATE(YEAR(SETUP!$B$8),MONTH(SETUP!$B$8)+2,1),JOURNAL!$A$5:$A$504,"<="&EOMONTH(SETUP!$B$8,2))-SUMIFS(JOURNAL!$J$5:$J$504,JOURNAL!$C$5:$C$504,$A8,JOURNAL!$A$5:$A$504,">="&DATE(YEAR(SETUP!$B$8),MONTH(SETUP!$B$8)+2,1),JOURNAL!$A$5:$A$504,"<="&EOMONTH(SETUP!$B$8,2)) | F8: =SUMIFS(JOURNAL!$I$5:$I$504,JOURNAL!$C$5:$C$504,$A8,JOURNAL!$A$5:$A$504,">="&DATE(YEAR(SETUP!$B$8),MONTH(SETUP!$B$8)+3,1),JOURNAL!$A$5:$A$504,"<="&EOMONTH(SETUP!$B$8,3))-SUMIFS(JOURNAL!$J$5:$J$504,JOURNAL!$C$5:$C$504,$A8,JOURNAL!$A$5:$A$504,">="&DATE(YEAR(SETUP!$B$8),MONTH(SETUP!$B$8)+3,1),JOURNAL!$A$5:$A$504,"<="&EOMONTH(SETUP!$B$8,3)) | G8: =SUMIFS(JOURNAL!$I$5:$I$504,JOURNAL!$C$5:$C$504,$A8,JOURNAL!$A$5:$A$504,">="&DATE(YEAR(SETUP!$B$8),MONTH(SETUP!$B$8)+4,1),JOURNAL!$A$5:$A$504,"<="&EOMONTH(SETUP!$B$8,4))-SUMIFS(JOURNAL!$J$5:$J$504,JOURNAL!$C$5:$C$504,$A8,JOURNAL!$A$5:$A$504,">="&DATE(YEAR(SETUP!$B$8),MONTH(SETUP!$B$8)+4,1),JOURNAL!$A$5:$A$504,"<="&EOMONTH(SETUP!$B$8,4)) | H8: =SUMIFS(JOURNAL!$I$5:$I$504,JOURNAL!$C$5:$C$504,$A8,JOURNAL!$A$5:$A$504,">="&DATE(YEAR(SETUP!$B$8),MONTH(SETUP!$B$8)+5,1),JOURNAL!$A$5:$A$504,"<="&EOMONTH(SETUP!$B$8,5))-SUMIFS(JOURNAL!$J$5:$J$504,JOURNAL!$C$5:$C$504,$A8,JOURNAL!$A$5:$A$504,">="&DATE(YEAR(SETUP!$B$8),MONTH(SETUP!$B$8)+5,1),JOURNAL!$A$5:$A$504,"<="&EOMONTH(SETUP!$B$8,5)) | I8: =SUMIFS(JOURNAL!$I$5:$I$504,JOURNAL!$C$5:$C$504,$A8,JOURNAL!$A$5:$A$504,">="&DATE(YEAR(SETUP!$B$8),MONTH(SETUP!$B$8)+6,1),JOURNAL!$A$5:$A$504,"<="&EOMONTH(SETUP!$B$8,6))-SUMIFS(JOURNAL!$J$5:$J$504,JOURNAL!$C$5:$C$504,$A8,JOURNAL!$A$5:$A$504,">="&DATE(YEAR(SETUP!$B$8),MONTH(SETUP!$B$8)+6,1),JOURNAL!$A$5:$A$504,"<="&EOMONTH(SETUP!$B$8,6)) | J8: =SUMIFS(JOURNAL!$I$5:$I$504,JOURNAL!$C$5:$C$504,$A8,JOURNAL!$A$5:$A$504,">="&DATE(YEAR(SETUP!$B$8),MONTH(SETUP!$B$8)+7,1),JOURNAL!$A$5:$A$504,"<="&EOMONTH(SETUP!$B$8,7))-SUMIFS(JOURNAL!$J$5:$J$504,JOURNAL!$C$5:$C$504,$A8,JOURNAL!$A$5:$A$504,">="&DATE(YEAR(SETUP!$B$8),MONTH(SETUP!$B$8)+7,1),JOURNAL!$A$5:$A$504,"<="&EOMONTH(SETUP!$B$8,7)) | K8: =SUMIFS(JOURNAL!$I$5:$I$504,JOURNAL!$C$5:$C$504,$A8,JOURNAL!$A$5:$A$504,">="&DATE(YEAR(SETUP!$B$8),MONTH(SETUP!$B$8)+8,1),JOURNAL!$A$5:$A$504,"<="&EOMONTH(SETUP!$B$8,8))-SUMIFS(JOURNAL!$J$5:$J$504,JOURNAL!$C$5:$C$504,$A8,JOURNAL!$A$5:$A$504,">="&DATE(YEAR(SETUP!$B$8),MONTH(SETUP!$B$8)+8,1),JOURNAL!$A$5:$A$504,"<="&EOMONTH(SETUP!$B$8,8)) | L8: =SUMIFS(JOURNAL!$I$5:$I$504,JOURNAL!$C$5:$C$504,$A8,JOURNAL!$A$5:$A$504,">="&DATE(YEAR(SETUP!$B$8),MONTH(SETUP!$B$8)+9,1),JOURNAL!$A$5:$A$504,"<="&EOMONTH(SETUP!$B$8,9))-SUMIFS(JOURNAL!$J$5:$J$504,JOURNAL!$C$5:$C$504,$A8,JOURNAL!$A$5:$A$504,">="&DATE(YEAR(SETUP!$B$8),MONTH(SETUP!$B$8)+9,1),JOURNAL!$A$5:$A$504,"<="&EOMONTH(SETUP!$B$8,9)) | M8: =SUMIFS(JOURNAL!$I$5:$I$504,JOURNAL!$C$5:$C$504,$A8,JOURNAL!$A$5:$A$504,">="&DATE(YEAR(SETUP!$B$8),MONTH(SETUP!$B$8)+10,1),JOURNAL!$A$5:$A$504,"<="&EOMONTH(SETUP!$B$8,10))-SUMIFS(JOURNAL!$J$5:$J$504,JOURNAL!$C$5:$C$504,$A8,JOURNAL!$A$5:$A$504,">="&DATE(YEAR(SETUP!$B$8),MONTH(SETUP!$B$8)+10,1),JOURNAL!$A$5:$A$504,"<="&EOMONTH(SETUP!$B$8,10)) | N8: =SUMIFS(JOURNAL!$I$5:$I$504,JOURNAL!$C$5:$C$504,$A8,JOURNAL!$A$5:$A$504,">="&DATE(YEAR(SETUP!$B$8),MONTH(SETUP!$B$8)+11,1),JOURNAL!$A$5:$A$504,"<="&EOMONTH(SETUP!$B$8,11))-SUMIFS(JOURNAL!$J$5:$J$504,JOURNAL!$C$5:$C$504,$A8,JOURNAL!$A$5:$A$504,">="&DATE(YEAR(SETUP!$B$8),MONTH(SETUP!$B$8)+11,1),JOURNAL!$A$5:$A$504,"<="&EOMONTH(SETUP!$B$8,11)) | O8: =SUM(C8:N8)
A9: 1200 | B9: Inventory — preforms and bottles | C9: =SUMIFS(JOURNAL!$I$5:$I$504,JOURNAL!$C$5:$C$504,$A9,JOURNAL!$A$5:$A$504,">="&DATE(YEAR(SETUP!$B$8),MONTH(SETUP!$B$8)+0,1),JOURNAL!$A$5:$A$504,"<="&EOMONTH(SETUP!$B$8,0))-SUMIFS(JOURNAL!$J$5:$J$504,JOURNAL!$C$5:$C$504,$A9,JOURNAL!$A$5:$A$504,">="&DATE(YEAR(SETUP!$B$8),MONTH(SETUP!$B$8)+0,1),JOURNAL!$A$5:$A$504,"<="&EOMONTH(SETUP!$B$8,0)) | D9: =SUMIFS(JOURNAL!$I$5:$I$504,JOURNAL!$C$5:$C$504,$A9,JOURNAL!$A$5:$A$504,">="&DATE(YEAR(SETUP!$B$8),MONTH(SETUP!$B$8)+1,1),JOURNAL!$A$5:$A$504,"<="&EOMONTH(SETUP!$B$8,1))-SUMIFS(JOURNAL!$J$5:$J$504,JOURNAL!$C$5:$C$504,$A9,JOURNAL!$A$5:$A$504,">="&DATE(YEAR(SETUP!$B$8),MONTH(SETUP!$B$8)+1,1),JOURNAL!$A$5:$A$504,"<="&EOMONTH(SETUP!$B$8,1)) | E9: =SUMIFS(JOURNAL!$I$5:$I$504,JOURNAL!$C$5:$C$504,$A9,JOURNAL!$A$5:$A$504,">="&DATE(YEAR(SETUP!$B$8),MONTH(SETUP!$B$8)+2,1),JOURNAL!$A$5:$A$504,"<="&EOMONTH(SETUP!$B$8,2))-SUMIFS(JOURNAL!$J$5:$J$504,JOURNAL!$C$5:$C$504,$A9,JOURNAL!$A$5:$A$504,">="&DATE(YEAR(SETUP!$B$8),MONTH(SETUP!$B$8)+2,1),JOURNAL!$A$5:$A$504,"<="&EOMONTH(SETUP!$B$8,2)) | F9: =SUMIFS(JOURNAL!$I$5:$I$504,JOURNAL!$C$5:$C$504,$A9,JOURNAL!$A$5:$A$504,">="&DATE(YEAR(SETUP!$B$8),MONTH(SETUP!$B$8)+3,1),JOURNAL!$A$5:$A$504,"<="&EOMONTH(SETUP!$B$8,3))-SUMIFS(JOURNAL!$J$5:$J$504,JOURNAL!$C$5:$C$504,$A9,JOURNAL!$A$5:$A$504,">="&DATE(YEAR(SETUP!$B$8),MONTH(SETUP!$B$8)+3,1),JOURNAL!$A$5:$A$504,"<="&EOMONTH(SETUP!$B$8,3)) | G9: =SUMIFS(JOURNAL!$I$5:$I$504,JOURNAL!$C$5:$C$504,$A9,JOURNAL!$A$5:$A$504,">="&DATE(YEAR(SETUP!$B$8),MONTH(SETUP!$B$8)+4,1),JOURNAL!$A$5:$A$504,"<="&EOMONTH(SETUP!$B$8,4))-SUMIFS(JOURNAL!$J$5:$J$504,JOURNAL!$C$5:$C$504,$A9,JOURNAL!$A$5:$A$504,">="&DATE(YEAR(SETUP!$B$8),MONTH(SETUP!$B$8)+4,1),JOURNAL!$A$5:$A$504,"<="&EOMONTH(SETUP!$B$8,4)) | H9: =SUMIFS(JOURNAL!$I$5:$I$504,JOURNAL!$C$5:$C$504,$A9,JOURNAL!$A$5:$A$504,">="&DATE(YEAR(SETUP!$B$8),MONTH(SETUP!$B$8)+5,1),JOURNAL!$A$5:$A$504,"<="&EOMONTH(SETUP!$B$8,5))-SUMIFS(JOURNAL!$J$5:$J$504,JOURNAL!$C$5:$C$504,$A9,JOURNAL!$A$5:$A$504,">="&DATE(YEAR(SETUP!$B$8),MONTH(SETUP!$B$8)+5,1),JOURNAL!$A$5:$A$504,"<="&EOMONTH(SETUP!$B$8,5)) | I9: =SUMIFS(JOURNAL!$I$5:$I$504,JOURNAL!$C$5:$C$504,$A9,JOURNAL!$A$5:$A$504,">="&DATE(YEAR(SETUP!$B$8),MONTH(SETUP!$B$8)+6,1),JOURNAL!$A$5:$A$504,"<="&EOMONTH(SETUP!$B$8,6))-SUMIFS(JOURNAL!$J$5:$J$504,JOURNAL!$C$5:$C$504,$A9,JOURNAL!$A$5:$A$504,">="&DATE(YEAR(SETUP!$B$8),MONTH(SETUP!$B$8)+6,1),JOURNAL!$A$5:$A$504,"<="&EOMONTH(SETUP!$B$8,6)) | J9: =SUMIFS(JOURNAL!$I$5:$I$504,JOURNAL!$C$5:$C$504,$A9,JOURNAL!$A$5:$A$504,">="&DATE(YEAR(SETUP!$B$8),MONTH(SETUP!$B$8)+7,1),JOURNAL!$A$5:$A$504,"<="&EOMONTH(SETUP!$B$8,7))-SUMIFS(JOURNAL!$J$5:$J$504,JOURNAL!$C$5:$C$504,$A9,JOURNAL!$A$5:$A$504,">="&DATE(YEAR(SETUP!$B$8),MONTH(SETUP!$B$8)+7,1),JOURNAL!$A$5:$A$504,"<="&EOMONTH(SETUP!$B$8,7)) | K9: =SUMIFS(JOURNAL!$I$5:$I$504,JOURNAL!$C$5:$C$504,$A9,JOURNAL!$A$5:$A$504,">="&DATE(YEAR(SETUP!$B$8),MONTH(SETUP!$B$8)+8,1),JOURNAL!$A$5:$A$504,"<="&EOMONTH(SETUP!$B$8,8))-SUMIFS(JOURNAL!$J$5:$J$504,JOURNAL!$C$5:$C$504,$A9,JOURNAL!$A$5:$A$504,">="&DATE(YEAR(SETUP!$B$8),MONTH(SETUP!$B$8)+8,1),JOURNAL!$A$5:$A$504,"<="&EOMONTH(SETUP!$B$8,8)) | L9: =SUMIFS(JOURNAL!$I$5:$I$504,JOURNAL!$C$5:$C$504,$A9,JOURNAL!$A$5:$A$504,">="&DATE(YEAR(SETUP!$B$8),MONTH(SETUP!$B$8)+9,1),JOURNAL!$A$5:$A$504,"<="&EOMONTH(SETUP!$B$8,9))-SUMIFS(JOURNAL!$J$5:$J$504,JOURNAL!$C$5:$C$504,$A9,JOURNAL!$A$5:$A$504,">="&DATE(YEAR(SETUP!$B$8),MONTH(SETUP!$B$8)+9,1),JOURNAL!$A$5:$A$504,"<="&EOMONTH(SETUP!$B$8,9)) | M9: =SUMIFS(JOURNAL!$I$5:$I$504,JOURNAL!$C$5:$C$504,$A9,JOURNAL!$A$5:$A$504,">="&DATE(YEAR(SETUP!$B$8),MONTH(SETUP!$B$8)+10,1),JOURNAL!$A$5:$A$504,"<="&EOMONTH(SETUP!$B$8,10))-SUMIFS(JOURNAL!$J$5:$J$504,JOURNAL!$C$5:$C$504,$A9,JOURNAL!$A$5:$A$504,">="&DATE(YEAR(SETUP!$B$8),MONTH(SETUP!$B$8)+10,1),JOURNAL!$A$5:$A$504,"<="&EOMONTH(SETUP!$B$8,10)) | N9: =SUMIFS(JOURNAL!$I$5:$I$504,JOURNAL!$C$5:$C$504,$A9,JOURNAL!$A$5:$A$504,">="&DATE(YEAR(SETUP!$B$8),MONTH(SETUP!$B$8)+11,1),JOURNAL!$A$5:$A$504,"<="&EOMONTH(SETUP!$B$8,11))-SUMIFS(JOURNAL!$J$5:$J$504,JOURNAL!$C$5:$C$504,$A9,JOURNAL!$A$5:$A$504,">="&DATE(YEAR(SETUP!$B$8),MONTH(SETUP!$B$8)+11,1),JOURNAL!$A$5:$A$504,"<="&EOMONTH(SETUP!$B$8,11)) | O9: =SUM(C9:N9)
A10: 1210 | B10: Inventory — caps and labels | C10: =SUMIFS(JOURNAL!$I$5:$I$504,JOURNAL!$C$5:$C$504,$A10,JOURNAL!$A$5:$A$504,">="&DATE(YEAR(SETUP!$B$8),MONTH(SETUP!$B$8)+0,1),JOURNAL!$A$5:$A$504,"<="&EOMONTH(SETUP!$B$8,0))-SUMIFS(JOURNAL!$J$5:$J$504,JOURNAL!$C$5:$C$504,$A10,JOURNAL!$A$5:$A$504,">="&DATE(YEAR(SETUP!$B$8),MONTH(SETUP!$B$8)+0,1),JOURNAL!$A$5:$A$504,"<="&EOMONTH(SETUP!$B$8,0)) | D10: =SUMIFS(JOURNAL!$I$5:$I$504,JOURNAL!$C$5:$C$504,$A10,JOURNAL!$A$5:$A$504,">="&DATE(YEAR(SETUP!$B$8),MONTH(SETUP!$B$8)+1,1),JOURNAL!$A$5:$A$504,"<="&EOMONTH(SETUP!$B$8,1))-SUMIFS(JOURNAL!$J$5:$J$504,JOURNAL!$C$5:$C$504,$A10,JOURNAL!$A$5:$A$504,">="&DATE(YEAR(SETUP!$B$8),MONTH(SETUP!$B$8)+1,1),JOURNAL!$A$5:$A$504,"<="&EOMONTH(SETUP!$B$8,1)) | E10: =SUMIFS(JOURNAL!$I$5:$I$504,JOURNAL!$C$5:$C$504,$A10,JOURNAL!$A$5:$A$504,">="&DATE(YEAR(SETUP!$B$8),MONTH(SETUP!$B$8)+2,1),JOURNAL!$A$5:$A$504,"<="&EOMONTH(SETUP!$B$8,2))-SUMIFS(JOURNAL!$J$5:$J$504,JOURNAL!$C$5:$C$504,$A10,JOURNAL!$A$5:$A$504,">="&DATE(YEAR(SETUP!$B$8),MONTH(SETUP!$B$8)+2,1),JOURNAL!$A$5:$A$504,"<="&EOMONTH(SETUP!$B$8,2)) | F10: =SUMIFS(JOURNAL!$I$5:$I$504,JOURNAL!$C$5:$C$504,$A10,JOURNAL!$A$5:$A$504,">="&DATE(YEAR(SETUP!$B$8),MONTH(SETUP!$B$8)+3,1),JOURNAL!$A$5:$A$504,"<="&EOMONTH(SETUP!$B$8,3))-SUMIFS(JOURNAL!$J$5:$J$504,JOURNAL!$C$5:$C$504,$A10,JOURNAL!$A$5:$A$504,">="&DATE(YEAR(SETUP!$B$8),MONTH(SETUP!$B$8)+3,1),JOURNAL!$A$5:$A$504,"<="&EOMONTH(SETUP!$B$8,3)) | G10: =SUMIFS(JOURNAL!$I$5:$I$504,JOURNAL!$C$5:$C$504,$A10,JOURNAL!$A$5:$A$504,">="&DATE(YEAR(SETUP!$B$8),MONTH(SETUP!$B$8)+4,1),JOURNAL!$A$5:$A$504,"<="&EOMONTH(SETUP!$B$8,4))-SUMIFS(JOURNAL!$J$5:$J$504,JOURNAL!$C$5:$C$504,$A10,JOURNAL!$A$5:$A$504,">="&DATE(YEAR(SETUP!$B$8),MONTH(SETUP!$B$8)+4,1),JOURNAL!$A$5:$A$504,"<="&EOMONTH(SETUP!$B$8,4)) | H10: =SUMIFS(JOURNAL!$I$5:$I$504,JOURNAL!$C$5:$C$504,$A10,JOURNAL!$A$5:$A$504,">="&DATE(YEAR(SETUP!$B$8),MONTH(SETUP!$B$8)+5,1),JOURNAL!$A$5:$A$504,"<="&EOMONTH(SETUP!$B$8,5))-SUMIFS(JOURNAL!$J$5:$J$504,JOURNAL!$C$5:$C$504,$A10,JOURNAL!$A$5:$A$504,">="&DATE(YEAR(SETUP!$B$8),MONTH(SETUP!$B$8)+5,1),JOURNAL!$A$5:$A$504,"<="&EOMONTH(SETUP!$B$8,5)) | I10: =SUMIFS(JOURNAL!$I$5:$I$504,JOURNAL!$C$5:$C$504,$A10,JOURNAL!$A$5:$A$504,">="&DATE(YEAR(SETUP!$B$8),MONTH(SETUP!$B$8)+6,1),JOURNAL!$A$5:$A$504,"<="&EOMONTH(SETUP!$B$8,6))-SUMIFS(JOURNAL!$J$5:$J$504,JOURNAL!$C$5:$C$504,$A10,JOURNAL!$A$5:$A$504,">="&DATE(YEAR(SETUP!$B$8),MONTH(SETUP!$B$8)+6,1),JOURNAL!$A$5:$A$504,"<="&EOMONTH(SETUP!$B$8,6)) | J10: =SUMIFS(JOURNAL!$I$5:$I$504,JOURNAL!$C$5:$C$504,$A10,JOURNAL!$A$5:$A$504,">="&DATE(YEAR(SETUP!$B$8),MONTH(SETUP!$B$8)+7,1),JOURNAL!$A$5:$A$504,"<="&EOMONTH(SETUP!$B$8,7))-SUMIFS(JOURNAL!$J$5:$J$504,JOURNAL!$C$5:$C$504,$A10,JOURNAL!$A$5:$A$504,">="&DATE(YEAR(SETUP!$B$8),MONTH(SETUP!$B$8)+7,1),JOURNAL!$A$5:$A$504,"<="&EOMONTH(SETUP!$B$8,7)) | K10: =SUMIFS(JOURNAL!$I$5:$I$504,JOURNAL!$C$5:$C$504,$A10,JOURNAL!$A$5:$A$504,">="&DATE(YEAR(SETUP!$B$8),MONTH(SETUP!$B$8)+8,1),JOURNAL!$A$5:$A$504,"<="&EOMONTH(SETUP!$B$8,8))-SUMIFS(JOURNAL!$J$5:$J$504,JOURNAL!$C$5:$C$504,$A10,JOURNAL!$A$5:$A$504,">="&DATE(YEAR(SETUP!$B$8),MONTH(SETUP!$B$8)+8,1),JOURNAL!$A$5:$A$504,"<="&EOMONTH(SETUP!$B$8,8)) | L10: =SUMIFS(JOURNAL!$I$5:$I$504,JOURNAL!$C$5:$C$504,$A10,JOURNAL!$A$5:$A$504,">="&DATE(YEAR(SETUP!$B$8),MONTH(SETUP!$B$8)+9,1),JOURNAL!$A$5:$A$504,"<="&EOMONTH(SETUP!$B$8,9))-SUMIFS(JOURNAL!$J$5:$J$504,JOURNAL!$C$5:$C$504,$A10,JOURNAL!$A$5:$A$504,">="&DATE(YEAR(SETUP!$B$8),MONTH(SETUP!$B$8)+9,1),JOURNAL!$A$5:$A$504,"<="&EOMONTH(SETUP!$B$8,9)) | M10: =SUMIFS(JOURNAL!$I$5:$I$504,JOURNAL!$C$5:$C$504,$A10,JOURNAL!$A$5:$A$504,">="&DATE(YEAR(SETUP!$B$8),MONTH(SETUP!$B$8)+10,1),JOURNAL!$A$5:$A$504,"<="&EOMONTH(SETUP!$B$8,10))-SUMIFS(JOURNAL!$J$5:$J$504,JOURNAL!$C$5:$C$504,$A10,JOURNAL!$A$5:$A$504,">="&DATE(YEAR(SETUP!$B$8),MONTH(SETUP!$B$8)+10,1),JOURNAL!$A$5:$A$504,"<="&EOMONTH(SETUP!$B$8,10)) | N10: =SUMIFS(JOURNAL!$I$5:$I$504,JOURNAL!$C$5:$C$504,$A10,JOURNAL!$A$5:$A$504,">="&DATE(YEAR(SETUP!$B$8),MONTH(SETUP!$B$8)+11,1),JOURNAL!$A$5:$A$504,"<="&EOMONTH(SETUP!$B$8,11))-SUMIFS(JOURNAL!$J$5:$J$504,JOURNAL!$C$5:$C$504,$A10,JOURNAL!$A$5:$A$504,">="&DATE(YEAR(SETUP!$B$8),MONTH(SETUP!$B$8)+11,1),JOURNAL!$A$5:$A$504,"<="&EOMONTH(SETUP!$B$8,11)) | O10: =SUM(C10:N10)
A11: 1220 | B11: Inventory — jars held for issue | C11: =SUMIFS(JOURNAL!$I$5:$I$504,JOURNAL!$C$5:$C$504,$A11,JOURNAL!$A$5:$A$504,">="&DATE(YEAR(SETUP!$B$8),MONTH(SETUP!$B$8)+0,1),JOURNAL!$A$5:$A$504,"<="&EOMONTH(SETUP!$B$8,0))-SUMIFS(JOURNAL!$J$5:$J$504,JOURNAL!$C$5:$C$504,$A11,JOURNAL!$A$5:$A$504,">="&DATE(YEAR(SETUP!$B$8),MONTH(SETUP!$B$8)+0,1),JOURNAL!$A$5:$A$504,"<="&EOMONTH(SETUP!$B$8,0)) | D11: =SUMIFS(JOURNAL!$I$5:$I$504,JOURNAL!$C$5:$C$504,$A11,JOURNAL!$A$5:$A$504,">="&DATE(YEAR(SETUP!$B$8),MONTH(SETUP!$B$8)+1,1),JOURNAL!$A$5:$A$504,"<="&EOMONTH(SETUP!$B$8,1))-SUMIFS(JOURNAL!$J$5:$J$504,JOURNAL!$C$5:$C$504,$A11,JOURNAL!$A$5:$A$504,">="&DATE(YEAR(SETUP!$B$8),MONTH(SETUP!$B$8)+1,1),JOURNAL!$A$5:$A$504,"<="&EOMONTH(SETUP!$B$8,1)) | E11: =SUMIFS(JOURNAL!$I$5:$I$504,JOURNAL!$C$5:$C$504,$A11,JOURNAL!$A$5:$A$504,">="&DATE(YEAR(SETUP!$B$8),MONTH(SETUP!$B$8)+2,1),JOURNAL!$A$5:$A$504,"<="&EOMONTH(SETUP!$B$8,2))-SUMIFS(JOURNAL!$J$5:$J$504,JOURNAL!$C$5:$C$504,$A11,JOURNAL!$A$5:$A$504,">="&DATE(YEAR(SETUP!$B$8),MONTH(SETUP!$B$8)+2,1),JOURNAL!$A$5:$A$504,"<="&EOMONTH(SETUP!$B$8,2)) | F11: =SUMIFS(JOURNAL!$I$5:$I$504,JOURNAL!$C$5:$C$504,$A11,JOURNAL!$A$5:$A$504,">="&DATE(YEAR(SETUP!$B$8),MONTH(SETUP!$B$8)+3,1),JOURNAL!$A$5:$A$504,"<="&EOMONTH(SETUP!$B$8,3))-SUMIFS(JOURNAL!$J$5:$J$504,JOURNAL!$C$5:$C$504,$A11,JOURNAL!$A$5:$A$504,">="&DATE(YEAR(SETUP!$B$8),MONTH(SETUP!$B$8)+3,1),JOURNAL!$A$5:$A$504,"<="&EOMONTH(SETUP!$B$8,3)) | G11: =SUMIFS(JOURNAL!$I$5:$I$504,JOURNAL!$C$5:$C$504,$A11,JOURNAL!$A$5:$A$504,">="&DATE(YEAR(SETUP!$B$8),MONTH(SETUP!$B$8)+4,1),JOURNAL!$A$5:$A$504,"<="&EOMONTH(SETUP!$B$8,4))-SUMIFS(JOURNAL!$J$5:$J$504,JOURNAL!$C$5:$C$504,$A11,JOURNAL!$A$5:$A$504,">="&DATE(YEAR(SETUP!$B$8),MONTH(SETUP!$B$8)+4,1),JOURNAL!$A$5:$A$504,"<="&EOMONTH(SETUP!$B$8,4)) | H11: =SUMIFS(JOURNAL!$I$5:$I$504,JOURNAL!$C$5:$C$504,$A11,JOURNAL!$A$5:$A$504,">="&DATE(YEAR(SETUP!$B$8),MONTH(SETUP!$B$8)+5,1),JOURNAL!$A$5:$A$504,"<="&EOMONTH(SETUP!$B$8,5))-SUMIFS(JOURNAL!$J$5:$J$504,JOURNAL!$C$5:$C$504,$A11,JOURNAL!$A$5:$A$504,">="&DATE(YEAR(SETUP!$B$8),MONTH(SETUP!$B$8)+5,1),JOURNAL!$A$5:$A$504,"<="&EOMONTH(SETUP!$B$8,5)) | I11: =SUMIFS(JOURNAL!$I$5:$I$504,JOURNAL!$C$5:$C$504,$A11,JOURNAL!$A$5:$A$504,">="&DATE(YEAR(SETUP!$B$8),MONTH(SETUP!$B$8)+6,1),JOURNAL!$A$5:$A$504,"<="&EOMONTH(SETUP!$B$8,6))-SUMIFS(JOURNAL!$J$5:$J$504,JOURNAL!$C$5:$C$504,$A11,JOURNAL!$A$5:$A$504,">="&DATE(YEAR(SETUP!$B$8),MONTH(SETUP!$B$8)+6,1),JOURNAL!$A$5:$A$504,"<="&EOMONTH(SETUP!$B$8,6)) | J11: =SUMIFS(JOURNAL!$I$5:$I$504,JOURNAL!$C$5:$C$504,$A11,JOURNAL!$A$5:$A$504,">="&DATE(YEAR(SETUP!$B$8),MONTH(SETUP!$B$8)+7,1),JOURNAL!$A$5:$A$504,"<="&EOMONTH(SETUP!$B$8,7))-SUMIFS(JOURNAL!$J$5:$J$504,JOURNAL!$C$5:$C$504,$A11,JOURNAL!$A$5:$A$504,">="&DATE(YEAR(SETUP!$B$8),MONTH(SETUP!$B$8)+7,1),JOURNAL!$A$5:$A$504,"<="&EOMONTH(SETUP!$B$8,7)) | K11: =SUMIFS(JOURNAL!$I$5:$I$504,JOURNAL!$C$5:$C$504,$A11,JOURNAL!$A$5:$A$504,">="&DATE(YEAR(SETUP!$B$8),MONTH(SETUP!$B$8)+8,1),JOURNAL!$A$5:$A$504,"<="&EOMONTH(SETUP!$B$8,8))-SUMIFS(JOURNAL!$J$5:$J$504,JOURNAL!$C$5:$C$504,$A11,JOURNAL!$A$5:$A$504,">="&DATE(YEAR(SETUP!$B$8),MONTH(SETUP!$B$8)+8,1),JOURNAL!$A$5:$A$504,"<="&EOMONTH(SETUP!$B$8,8)) | L11: =SUMIFS(JOURNAL!$I$5:$I$504,JOURNAL!$C$5:$C$504,$A11,JOURNAL!$A$5:$A$504,">="&DATE(YEAR(SETUP!$B$8),MONTH(SETUP!$B$8)+9,1),JOURNAL!$A$5:$A$504,"<="&EOMONTH(SETUP!$B$8,9))-SUMIFS(JOURNAL!$J$5:$J$504,JOURNAL!$C$5:$C$504,$A11,JOURNAL!$A$5:$A$504,">="&DATE(YEAR(SETUP!$B$8),MONTH(SETUP!$B$8)+9,1),JOURNAL!$A$5:$A$504,"<="&EOMONTH(SETUP!$B$8,9)) | M11: =SUMIFS(JOURNAL!$I$5:$I$504,JOURNAL!$C$5:$C$504,$A11,JOURNAL!$A$5:$A$504,">="&DATE(YEAR(SETUP!$B$8),MONTH(SETUP!$B$8)+10,1),JOURNAL!$A$5:$A$504,"<="&EOMONTH(SETUP!$B$8,10))-SUMIFS(JOURNAL!$J$5:$J$504,JOURNAL!$C$5:$C$504,$A11,JOURNAL!$A$5:$A$504,">="&DATE(YEAR(SETUP!$B$8),MONTH(SETUP!$B$8)+10,1),JOURNAL!$A$5:$A$504,"<="&EOMONTH(SETUP!$B$8,10)) | N11: =SUMIFS(JOURNAL!$I$5:$I$504,JOURNAL!$C$5:$C$504,$A11,JOURNAL!$A$5:$A$504,">="&DATE(YEAR(SETUP!$B$8),MONTH(SETUP!$B$8)+11,1),JOURNAL!$A$5:$A$504,"<="&EOMONTH(SETUP!$B$8,11))-SUMIFS(JOURNAL!$J$5:$J$504,JOURNAL!$C$5:$C$504,$A11,JOURNAL!$A$5:$A$504,">="&DATE(YEAR(SETUP!$B$8),MONTH(SETUP!$B$8)+11,1),JOURNAL!$A$5:$A$504,"<="&EOMONTH(SETUP!$B$8,11)) | O11: =SUM(C11:N11)
A12: 1230 | B12: Inventory — treatment consumables | C12: =SUMIFS(JOURNAL!$I$5:$I$504,JOURNAL!$C$5:$C$504,$A12,JOURNAL!$A$5:$A$504,">="&DATE(YEAR(SETUP!$B$8),MONTH(SETUP!$B$8)+0,1),JOURNAL!$A$5:$A$504,"<="&EOMONTH(SETUP!$B$8,0))-SUMIFS(JOURNAL!$J$5:$J$504,JOURNAL!$C$5:$C$504,$A12,JOURNAL!$A$5:$A$504,">="&DATE(YEAR(SETUP!$B$8),MONTH(SETUP!$B$8)+0,1),JOURNAL!$A$5:$A$504,"<="&EOMONTH(SETUP!$B$8,0)) | D12: =SUMIFS(JOURNAL!$I$5:$I$504,JOURNAL!$C$5:$C$504,$A12,JOURNAL!$A$5:$A$504,">="&DATE(YEAR(SETUP!$B$8),MONTH(SETUP!$B$8)+1,1),JOURNAL!$A$5:$A$504,"<="&EOMONTH(SETUP!$B$8,1))-SUMIFS(JOURNAL!$J$5:$J$504,JOURNAL!$C$5:$C$504,$A12,JOURNAL!$A$5:$A$504,">="&DATE(YEAR(SETUP!$B$8),MONTH(SETUP!$B$8)+1,1),JOURNAL!$A$5:$A$504,"<="&EOMONTH(SETUP!$B$8,1)) | E12: =SUMIFS(JOURNAL!$I$5:$I$504,JOURNAL!$C$5:$C$504,$A12,JOURNAL!$A$5:$A$504,">="&DATE(YEAR(SETUP!$B$8),MONTH(SETUP!$B$8)+2,1),JOURNAL!$A$5:$A$504,"<="&EOMONTH(SETUP!$B$8,2))-SUMIFS(JOURNAL!$J$5:$J$504,JOURNAL!$C$5:$C$504,$A12,JOURNAL!$A$5:$A$504,">="&DATE(YEAR(SETUP!$B$8),MONTH(SETUP!$B$8)+2,1),JOURNAL!$A$5:$A$504,"<="&EOMONTH(SETUP!$B$8,2)) | F12: =SUMIFS(JOURNAL!$I$5:$I$504,JOURNAL!$C$5:$C$504,$A12,JOURNAL!$A$5:$A$504,">="&DATE(YEAR(SETUP!$B$8),MONTH(SETUP!$B$8)+3,1),JOURNAL!$A$5:$A$504,"<="&EOMONTH(SETUP!$B$8,3))-SUMIFS(JOURNAL!$J$5:$J$504,JOURNAL!$C$5:$C$504,$A12,JOURNAL!$A$5:$A$504,">="&DATE(YEAR(SETUP!$B$8),MONTH(SETUP!$B$8)+3,1),JOURNAL!$A$5:$A$504,"<="&EOMONTH(SETUP!$B$8,3)) | G12: =SUMIFS(JOURNAL!$I$5:$I$504,JOURNAL!$C$5:$C$504,$A12,JOURNAL!$A$5:$A$504,">="&DATE(YEAR(SETUP!$B$8),MONTH(SETUP!$B$8)+4,1),JOURNAL!$A$5:$A$504,"<="&EOMONTH(SETUP!$B$8,4))-SUMIFS(JOURNAL!$J$5:$J$504,JOURNAL!$C$5:$C$504,$A12,JOURNAL!$A$5:$A$504,">="&DATE(YEAR(SETUP!$B$8),MONTH(SETUP!$B$8)+4,1),JOURNAL!$A$5:$A$504,"<="&EOMONTH(SETUP!$B$8,4)) | H12: =SUMIFS(JOURNAL!$I$5:$I$504,JOURNAL!$C$5:$C$504,$A12,JOURNAL!$A$5:$A$504,">="&DATE(YEAR(SETUP!$B$8),MONTH(SETUP!$B$8)+5,1),JOURNAL!$A$5:$A$504,"<="&EOMONTH(SETUP!$B$8,5))-SUMIFS(JOURNAL!$J$5:$J$504,JOURNAL!$C$5:$C$504,$A12,JOURNAL!$A$5:$A$504,">="&DATE(YEAR(SETUP!$B$8),MONTH(SETUP!$B$8)+5,1),JOURNAL!$A$5:$A$504,"<="&EOMONTH(SETUP!$B$8,5)) | I12: =SUMIFS(JOURNAL!$I$5:$I$504,JOURNAL!$C$5:$C$504,$A12,JOURNAL!$A$5:$A$504,">="&DATE(YEAR(SETUP!$B$8),MONTH(SETUP!$B$8)+6,1),JOURNAL!$A$5:$A$504,"<="&EOMONTH(SETUP!$B$8,6))-SUMIFS(JOURNAL!$J$5:$J$504,JOURNAL!$C$5:$C$504,$A12,JOURNAL!$A$5:$A$504,">="&DATE(YEAR(SETUP!$B$8),MONTH(SETUP!$B$8)+6,1),JOURNAL!$A$5:$A$504,"<="&EOMONTH(SETUP!$B$8,6)) | J12: =SUMIFS(JOURNAL!$I$5:$I$504,JOURNAL!$C$5:$C$504,$A12,JOURNAL!$A$5:$A$504,">="&DATE(YEAR(SETUP!$B$8),MONTH(SETUP!$B$8)+7,1),JOURNAL!$A$5:$A$504,"<="&EOMONTH(SETUP!$B$8,7))-SUMIFS(JOURNAL!$J$5:$J$504,JOURNAL!$C$5:$C$504,$A12,JOURNAL!$A$5:$A$504,">="&DATE(YEAR(SETUP!$B$8),MONTH(SETUP!$B$8)+7,1),JOURNAL!$A$5:$A$504,"<="&EOMONTH(SETUP!$B$8,7)) | K12: =SUMIFS(JOURNAL!$I$5:$I$504,JOURNAL!$C$5:$C$504,$A12,JOURNAL!$A$5:$A$504,">="&DATE(YEAR(SETUP!$B$8),MONTH(SETUP!$B$8)+8,1),JOURNAL!$A$5:$A$504,"<="&EOMONTH(SETUP!$B$8,8))-SUMIFS(JOURNAL!$J$5:$J$504,JOURNAL!$C$5:$C$504,$A12,JOURNAL!$A$5:$A$504,">="&DATE(YEAR(SETUP!$B$8),MONTH(SETUP!$B$8)+8,1),JOURNAL!$A$5:$A$504,"<="&EOMONTH(SETUP!$B$8,8)) | L12: =SUMIFS(JOURNAL!$I$5:$I$504,JOURNAL!$C$5:$C$504,$A12,JOURNAL!$A$5:$A$504,">="&DATE(YEAR(SETUP!$B$8),MONTH(SETUP!$B$8)+9,1),JOURNAL!$A$5:$A$504,"<="&EOMONTH(SETUP!$B$8,9))-SUMIFS(JOURNAL!$J$5:$J$504,JOURNAL!$C$5:$C$504,$A12,JOURNAL!$A$5:$A$504,">="&DATE(YEAR(SETUP!$B$8),MONTH(SETUP!$B$8)+9,1),JOURNAL!$A$5:$A$504,"<="&EOMONTH(SETUP!$B$8,9)) | M12: =SUMIFS(JOURNAL!$I$5:$I$504,JOURNAL!$C$5:$C$504,$A12,JOURNAL!$A$5:$A$504,">="&DATE(YEAR(SETUP!$B$8),MONTH(SETUP!$B$8)+10,1),JOURNAL!$A$5:$A$504,"<="&EOMONTH(SETUP!$B$8,10))-SUMIFS(JOURNAL!$J$5:$J$504,JOURNAL!$C$5:$C$504,$A12,JOURNAL!$A$5:$A$504,">="&DATE(YEAR(SETUP!$B$8),MONTH(SETUP!$B$8)+10,1),JOURNAL!$A$5:$A$504,"<="&EOMONTH(SETUP!$B$8,10)) | N12: =SUMIFS(JOURNAL!$I$5:$I$504,JOURNAL!$C$5:$C$504,$A12,JOURNAL!$A$5:$A$504,">="&DATE(YEAR(SETUP!$B$8),MONTH(SETUP!$B$8)+11,1),JOURNAL!$A$5:$A$504,"<="&EOMONTH(SETUP!$B$8,11))-SUMIFS(JOURNAL!$J$5:$J$504,JOURNAL!$C$5:$C$504,$A12,JOURNAL!$A$5:$A$504,">="&DATE(YEAR(SETUP!$B$8),MONTH(SETUP!$B$8)+11,1),JOURNAL!$A$5:$A$504,"<="&EOMONTH(SETUP!$B$8,11)) | O12: =SUM(C12:N12)
A13: 1300 | B13: Input VAT recoverable | C13: =SUMIFS(JOURNAL!$I$5:$I$504,JOURNAL!$C$5:$C$504,$A13,JOURNAL!$A$5:$A$504,">="&DATE(YEAR(SETUP!$B$8),MONTH(SETUP!$B$8)+0,1),JOURNAL!$A$5:$A$504,"<="&EOMONTH(SETUP!$B$8,0))-SUMIFS(JOURNAL!$J$5:$J$504,JOURNAL!$C$5:$C$504,$A13,JOURNAL!$A$5:$A$504,">="&DATE(YEAR(SETUP!$B$8),MONTH(SETUP!$B$8)+0,1),JOURNAL!$A$5:$A$504,"<="&EOMONTH(SETUP!$B$8,0)) | D13: =SUMIFS(JOURNAL!$I$5:$I$504,JOURNAL!$C$5:$C$504,$A13,JOURNAL!$A$5:$A$504,">="&DATE(YEAR(SETUP!$B$8),MONTH(SETUP!$B$8)+1,1),JOURNAL!$A$5:$A$504,"<="&EOMONTH(SETUP!$B$8,1))-SUMIFS(JOURNAL!$J$5:$J$504,JOURNAL!$C$5:$C$504,$A13,JOURNAL!$A$5:$A$504,">="&DATE(YEAR(SETUP!$B$8),MONTH(SETUP!$B$8)+1,1),JOURNAL!$A$5:$A$504,"<="&EOMONTH(SETUP!$B$8,1)) | E13: =SUMIFS(JOURNAL!$I$5:$I$504,JOURNAL!$C$5:$C$504,$A13,JOURNAL!$A$5:$A$504,">="&DATE(YEAR(SETUP!$B$8),MONTH(SETUP!$B$8)+2,1),JOURNAL!$A$5:$A$504,"<="&EOMONTH(SETUP!$B$8,2))-SUMIFS(JOURNAL!$J$5:$J$504,JOURNAL!$C$5:$C$504,$A13,JOURNAL!$A$5:$A$504,">="&DATE(YEAR(SETUP!$B$8),MONTH(SETUP!$B$8)+2,1),JOURNAL!$A$5:$A$504,"<="&EOMONTH(SETUP!$B$8,2)) | F13: =SUMIFS(JOURNAL!$I$5:$I$504,JOURNAL!$C$5:$C$504,$A13,JOURNAL!$A$5:$A$504,">="&DATE(YEAR(SETUP!$B$8),MONTH(SETUP!$B$8)+3,1),JOURNAL!$A$5:$A$504,"<="&EOMONTH(SETUP!$B$8,3))-SUMIFS(JOURNAL!$J$5:$J$504,JOURNAL!$C$5:$C$504,$A13,JOURNAL!$A$5:$A$504,">="&DATE(YEAR(SETUP!$B$8),MONTH(SETUP!$B$8)+3,1),JOURNAL!$A$5:$A$504,"<="&EOMONTH(SETUP!$B$8,3)) | G13: =SUMIFS(JOURNAL!$I$5:$I$504,JOURNAL!$C$5:$C$504,$A13,JOURNAL!$A$5:$A$504,">="&DATE(YEAR(SETUP!$B$8),MONTH(SETUP!$B$8)+4,1),JOURNAL!$A$5:$A$504,"<="&EOMONTH(SETUP!$B$8,4))-SUMIFS(JOURNAL!$J$5:$J$504,JOURNAL!$C$5:$C$504,$A13,JOURNAL!$A$5:$A$504,">="&DATE(YEAR(SETUP!$B$8),MONTH(SETUP!$B$8)+4,1),JOURNAL!$A$5:$A$504,"<="&EOMONTH(SETUP!$B$8,4)) | H13: =SUMIFS(JOURNAL!$I$5:$I$504,JOURNAL!$C$5:$C$504,$A13,JOURNAL!$A$5:$A$504,">="&DATE(YEAR(SETUP!$B$8),MONTH(SETUP!$B$8)+5,1),JOURNAL!$A$5:$A$504,"<="&EOMONTH(SETUP!$B$8,5))-SUMIFS(JOURNAL!$J$5:$J$504,JOURNAL!$C$5:$C$504,$A13,JOURNAL!$A$5:$A$504,">="&DATE(YEAR(SETUP!$B$8),MONTH(SETUP!$B$8)+5,1),JOURNAL!$A$5:$A$504,"<="&EOMONTH(SETUP!$B$8,5)) | I13: =SUMIFS(JOURNAL!$I$5:$I$504,JOURNAL!$C$5:$C$504,$A13,JOURNAL!$A$5:$A$504,">="&DATE(YEAR(SETUP!$B$8),MONTH(SETUP!$B$8)+6,1),JOURNAL!$A$5:$A$504,"<="&EOMONTH(SETUP!$B$8,6))-SUMIFS(JOURNAL!$J$5:$J$504,JOURNAL!$C$5:$C$504,$A13,JOURNAL!$A$5:$A$504,">="&DATE(YEAR(SETUP!$B$8),MONTH(SETUP!$B$8)+6,1),JOURNAL!$A$5:$A$504,"<="&EOMONTH(SETUP!$B$8,6)) | J13: =SUMIFS(JOURNAL!$I$5:$I$504,JOURNAL!$C$5:$C$504,$A13,JOURNAL!$A$5:$A$504,">="&DATE(YEAR(SETUP!$B$8),MONTH(SETUP!$B$8)+7,1),JOURNAL!$A$5:$A$504,"<="&EOMONTH(SETUP!$B$8,7))-SUMIFS(JOURNAL!$J$5:$J$504,JOURNAL!$C$5:$C$504,$A13,JOURNAL!$A$5:$A$504,">="&DATE(YEAR(SETUP!$B$8),MONTH(SETUP!$B$8)+7,1),JOURNAL!$A$5:$A$504,"<="&EOMONTH(SETUP!$B$8,7)) | K13: =SUMIFS(JOURNAL!$I$5:$I$504,JOURNAL!$C$5:$C$504,$A13,JOURNAL!$A$5:$A$504,">="&DATE(YEAR(SETUP!$B$8),MONTH(SETUP!$B$8)+8,1),JOURNAL!$A$5:$A$504,"<="&EOMONTH(SETUP!$B$8,8))-SUMIFS(JOURNAL!$J$5:$J$504,JOURNAL!$C$5:$C$504,$A13,JOURNAL!$A$5:$A$504,">="&DATE(YEAR(SETUP!$B$8),MONTH(SETUP!$B$8)+8,1),JOURNAL!$A$5:$A$504,"<="&EOMONTH(SETUP!$B$8,8)) | L13: =SUMIFS(JOURNAL!$I$5:$I$504,JOURNAL!$C$5:$C$504,$A13,JOURNAL!$A$5:$A$504,">="&DATE(YEAR(SETUP!$B$8),MONTH(SETUP!$B$8)+9,1),JOURNAL!$A$5:$A$504,"<="&EOMONTH(SETUP!$B$8,9))-SUMIFS(JOURNAL!$J$5:$J$504,JOURNAL!$C$5:$C$504,$A13,JOURNAL!$A$5:$A$504,">="&DATE(YEAR(SETUP!$B$8),MONTH(SETUP!$B$8)+9,1),JOURNAL!$A$5:$A$504,"<="&EOMONTH(SETUP!$B$8,9)) | M13: =SUMIFS(JOURNAL!$I$5:$I$504,JOURNAL!$C$5:$C$504,$A13,JOURNAL!$A$5:$A$504,">="&DATE(YEAR(SETUP!$B$8),MONTH(SETUP!$B$8)+10,1),JOURNAL!$A$5:$A$504,"<="&EOMONTH(SETUP!$B$8,10))-SUMIFS(JOURNAL!$J$5:$J$504,JOURNAL!$C$5:$C$504,$A13,JOURNAL!$A$5:$A$504,">="&DATE(YEAR(SETUP!$B$8),MONTH(SETUP!$B$8)+10,1),JOURNAL!$A$5:$A$504,"<="&EOMONTH(SETUP!$B$8,10)) | N13: =SUMIFS(JOURNAL!$I$5:$I$504,JOURNAL!$C$5:$C$504,$A13,JOURNAL!$A$5:$A$504,">="&DATE(YEAR(SETUP!$B$8),MONTH(SETUP!$B$8)+11,1),JOURNAL!$A$5:$A$504,"<="&EOMONTH(SETUP!$B$8,11))-SUMIFS(JOURNAL!$J$5:$J$504,JOURNAL!$C$5:$C$504,$A13,JOURNAL!$A$5:$A$504,">="&DATE(YEAR(SETUP!$B$8),MONTH(SETUP!$B$8)+11,1),JOURNAL!$A$5:$A$504,"<="&EOMONTH(SETUP!$B$8,11)) | O13: =SUM(C13:N13)
A14: 1500 | B14: Plant and equipment at cost | C14: =SUMIFS(JOURNAL!$I$5:$I$504,JOURNAL!$C$5:$C$504,$A14,JOURNAL!$A$5:$A$504,">="&DATE(YEAR(SETUP!$B$8),MONTH(SETUP!$B$8)+0,1),JOURNAL!$A$5:$A$504,"<="&EOMONTH(SETUP!$B$8,0))-SUMIFS(JOURNAL!$J$5:$J$504,JOURNAL!$C$5:$C$504,$A14,JOURNAL!$A$5:$A$504,">="&DATE(YEAR(SETUP!$B$8),MONTH(SETUP!$B$8)+0,1),JOURNAL!$A$5:$A$504,"<="&EOMONTH(SETUP!$B$8,0)) | D14: =SUMIFS(JOURNAL!$I$5:$I$504,JOURNAL!$C$5:$C$504,$A14,JOURNAL!$A$5:$A$504,">="&DATE(YEAR(SETUP!$B$8),MONTH(SETUP!$B$8)+1,1),JOURNAL!$A$5:$A$504,"<="&EOMONTH(SETUP!$B$8,1))-SUMIFS(JOURNAL!$J$5:$J$504,JOURNAL!$C$5:$C$504,$A14,JOURNAL!$A$5:$A$504,">="&DATE(YEAR(SETUP!$B$8),MONTH(SETUP!$B$8)+1,1),JOURNAL!$A$5:$A$504,"<="&EOMONTH(SETUP!$B$8,1)) | E14: =SUMIFS(JOURNAL!$I$5:$I$504,JOURNAL!$C$5:$C$504,$A14,JOURNAL!$A$5:$A$504,">="&DATE(YEAR(SETUP!$B$8),MONTH(SETUP!$B$8)+2,1),JOURNAL!$A$5:$A$504,"<="&EOMONTH(SETUP!$B$8,2))-SUMIFS(JOURNAL!$J$5:$J$504,JOURNAL!$C$5:$C$504,$A14,JOURNAL!$A$5:$A$504,">="&DATE(YEAR(SETUP!$B$8),MONTH(SETUP!$B$8)+2,1),JOURNAL!$A$5:$A$504,"<="&EOMONTH(SETUP!$B$8,2)) | F14: =SUMIFS(JOURNAL!$I$5:$I$504,JOURNAL!$C$5:$C$504,$A14,JOURNAL!$A$5:$A$504,">="&DATE(YEAR(SETUP!$B$8),MONTH(SETUP!$B$8)+3,1),JOURNAL!$A$5:$A$504,"<="&EOMONTH(SETUP!$B$8,3))-SUMIFS(JOURNAL!$J$5:$J$504,JOURNAL!$C$5:$C$504,$A14,JOURNAL!$A$5:$A$504,">="&DATE(YEAR(SETUP!$B$8),MONTH(SETUP!$B$8)+3,1),JOURNAL!$A$5:$A$504,"<="&EOMONTH(SETUP!$B$8,3)) | G14: =SUMIFS(JOURNAL!$I$5:$I$504,JOURNAL!$C$5:$C$504,$A14,JOURNAL!$A$5:$A$504,">="&DATE(YEAR(SETUP!$B$8),MONTH(SETUP!$B$8)+4,1),JOURNAL!$A$5:$A$504,"<="&EOMONTH(SETUP!$B$8,4))-SUMIFS(JOURNAL!$J$5:$J$504,JOURNAL!$C$5:$C$504,$A14,JOURNAL!$A$5:$A$504,">="&DATE(YEAR(SETUP!$B$8),MONTH(SETUP!$B$8)+4,1),JOURNAL!$A$5:$A$504,"<="&EOMONTH(SETUP!$B$8,4)) | H14: =SUMIFS(JOURNAL!$I$5:$I$504,JOURNAL!$C$5:$C$504,$A14,JOURNAL!$A$5:$A$504,">="&DATE(YEAR(SETUP!$B$8),MONTH(SETUP!$B$8)+5,1),JOURNAL!$A$5:$A$504,"<="&EOMONTH(SETUP!$B$8,5))-SUMIFS(JOURNAL!$J$5:$J$504,JOURNAL!$C$5:$C$504,$A14,JOURNAL!$A$5:$A$504,">="&DATE(YEAR(SETUP!$B$8),MONTH(SETUP!$B$8)+5,1),JOURNAL!$A$5:$A$504,"<="&EOMONTH(SETUP!$B$8,5)) | I14: =SUMIFS(JOURNAL!$I$5:$I$504,JOURNAL!$C$5:$C$504,$A14,JOURNAL!$A$5:$A$504,">="&DATE(YEAR(SETUP!$B$8),MONTH(SETUP!$B$8)+6,1),JOURNAL!$A$5:$A$504,"<="&EOMONTH(SETUP!$B$8,6))-SUMIFS(JOURNAL!$J$5:$J$504,JOURNAL!$C$5:$C$504,$A14,JOURNAL!$A$5:$A$504,">="&DATE(YEAR(SETUP!$B$8),MONTH(SETUP!$B$8)+6,1),JOURNAL!$A$5:$A$504,"<="&EOMONTH(SETUP!$B$8,6)) | J14: =SUMIFS(JOURNAL!$I$5:$I$504,JOURNAL!$C$5:$C$504,$A14,JOURNAL!$A$5:$A$504,">="&DATE(YEAR(SETUP!$B$8),MONTH(SETUP!$B$8)+7,1),JOURNAL!$A$5:$A$504,"<="&EOMONTH(SETUP!$B$8,7))-SUMIFS(JOURNAL!$J$5:$J$504,JOURNAL!$C$5:$C$504,$A14,JOURNAL!$A$5:$A$504,">="&DATE(YEAR(SETUP!$B$8),MONTH(SETUP!$B$8)+7,1),JOURNAL!$A$5:$A$504,"<="&EOMONTH(SETUP!$B$8,7)) | K14: =SUMIFS(JOURNAL!$I$5:$I$504,JOURNAL!$C$5:$C$504,$A14,JOURNAL!$A$5:$A$504,">="&DATE(YEAR(SETUP!$B$8),MONTH(SETUP!$B$8)+8,1),JOURNAL!$A$5:$A$504,"<="&EOMONTH(SETUP!$B$8,8))-SUMIFS(JOURNAL!$J$5:$J$504,JOURNAL!$C$5:$C$504,$A14,JOURNAL!$A$5:$A$504,">="&DATE(YEAR(SETUP!$B$8),MONTH(SETUP!$B$8)+8,1),JOURNAL!$A$5:$A$504,"<="&EOMONTH(SETUP!$B$8,8)) | L14: =SUMIFS(JOURNAL!$I$5:$I$504,JOURNAL!$C$5:$C$504,$A14,JOURNAL!$A$5:$A$504,">="&DATE(YEAR(SETUP!$B$8),MONTH(SETUP!$B$8)+9,1),JOURNAL!$A$5:$A$504,"<="&EOMONTH(SETUP!$B$8,9))-SUMIFS(JOURNAL!$J$5:$J$504,JOURNAL!$C$5:$C$504,$A14,JOURNAL!$A$5:$A$504,">="&DATE(YEAR(SETUP!$B$8),MONTH(SETUP!$B$8)+9,1),JOURNAL!$A$5:$A$504,"<="&EOMONTH(SETUP!$B$8,9)) | M14: =SUMIFS(JOURNAL!$I$5:$I$504,JOURNAL!$C$5:$C$504,$A14,JOURNAL!$A$5:$A$504,">="&DATE(YEAR(SETUP!$B$8),MONTH(SETUP!$B$8)+10,1),JOURNAL!$A$5:$A$504,"<="&EOMONTH(SETUP!$B$8,10))-SUMIFS(JOURNAL!$J$5:$J$504,JOURNAL!$C$5:$C$504,$A14,JOURNAL!$A$5:$A$504,">="&DATE(YEAR(SETUP!$B$8),MONTH(SETUP!$B$8)+10,1),JOURNAL!$A$5:$A$504,"<="&EOMONTH(SETUP!$B$8,10)) | N14: =SUMIFS(JOURNAL!$I$5:$I$504,JOURNAL!$C$5:$C$504,$A14,JOURNAL!$A$5:$A$504,">="&DATE(YEAR(SETUP!$B$8),MONTH(SETUP!$B$8)+11,1),JOURNAL!$A$5:$A$504,"<="&EOMONTH(SETUP!$B$8,11))-SUMIFS(JOURNAL!$J$5:$J$504,JOURNAL!$C$5:$C$504,$A14,JOURNAL!$A$5:$A$504,">="&DATE(YEAR(SETUP!$B$8),MONTH(SETUP!$B$8)+11,1),JOURNAL!$A$5:$A$504,"<="&EOMONTH(SETUP!$B$8,11)) | O14: =SUM(C14:N14)
